Workbook

Sheet dr edi dan tamu
B3: Rekap Makan dr edi | C3: Tanggal | AH3: Total | AI3: Harga | AJ3: Jumlah
C4: 1 | D4: 2 | E4: 3 | F4: 4 | G4: 5 | H4: 6 | I4: 7 | J4: 8 | K4: 9 | L4: 10 | M4: 11 | N4: 12 | O4: 13 | P4: 14 | Q4: 15 | R4: 16 | S4: 17 | T4: 18 | U4: 19 | V4: 20 | W4: 21 | X4: 22 | Y4: 23 | Z4: 24 | AA4: 25 | AB4: 26 | AC4: 27 | AD4: 28 | AE4: 29 | AF4: 30 | AG4: 31
B5: jml | C5: 1 | H5: 0 | J5: 1 | K5: 1 | L5: 0 | M5: 0 | N5: 0 | O5: 0 | Q5: 1 | R5: 0 | S5: 1 | T5: 0 | U5: 0 | V5: 0 | W5: 1 | X5: 0 | Z5: 1 | AA5: 1 | AC5: 0 | AH5: =SUM(C5:AG5) -> 8 | AI5: 30000 | AJ5: =AH5*AI5 -> 240000
B8: Rekap Snack dr edi | C8: buah | D8: le mineral 330 | E8: snack | F8: pocari | G8: buavita | H8: BEAR BRAND | I8: YAKULT | J8: PUDING' | K8: susu ultra mini | M8: tgl | N8: tamu | O8: snack | P8: roti | Q8: le mineral 330 | R8: cleo 240ml | T8: tgl | U8: management | V8: snack | W8: roti | X8: le mineral 330 | Y8: jus | Z8: cleo 240ml | AA8: Makan
B10: 1,9,26 | C10: 1 | D10: 2 | K10: 2 | T10: 05.09.2026 | U10: marketing | V10: 76 | X10: 48
B11: 2,9,26 | T11: 8,9,26 | U11: dr feny | V11: 10 | X11: 10
U12: tamu bunse | X12: 7
B13: 03.09.26 | D13: 2 | T13: 07.09.2026 | U13: pt | X13: 24
B14: 4,9,26 | T14: 07.09.26 | U14: aula 4a | X14: 15
B15: 46270 | C15: 0 | D15: 0 | E15: 0 | F15: 0 | G15: 0 | T15: 07.09.26 | U15: aula 4b | X15: 8
B16: 6,9,26 | C16: 0 | D16: 0 | T16: 11.9.26 | U16: snack haji | V16: 4
B17: 7,9,26 | D17: 2 | E17: 2 | T17: 12,9,26 | U17: mcu haji | V17: 2
B18: 8,9,26 | C18: 1 | D18: 2 | K18: 2 | U18: aula 4a | V18: 20 | X18: 24
B19: 09,09,2026 | E19: 2 | G19: 1 | I19: 1 | U19: pembicara dr amar aula1 | V19: 1 | X19: 2 | AA19: 1
B20: 10,09,2026 | C20: 1 | D20: 2 | T20: 14.09.26 | U20: rapat dr.fenny aula4a | X20: 15
B21: 11.9.26 | C21: 1 | D21: 2 | E21: 2 | I21: 2 | T21: 17,09,26 | U21: rapat dokter umum | X21: 25 | Y21: 25 | AA21: 25
B22: 12,9,26 | C22: 0 | D22: 0 | T22: 16.9.26 | U22: rapat mutu | W22: 20 | X22: 24
B23: 13.09.26 | C23: 0 | D23: 0 | E23: 0 | F23: 0 | U23: rapat pak sodik | X23: 20
B24: 14.09.26 | D24: 2 | E24: 2 | H24: 1 | U24: mfk | Z24: 40
B25: 15,9,26 | C25: 2 | D25: 2 | K25: 2 | U25: rapat adm | V25: 11 | X25: 31
B26: 16,05,2026 | D26: 2 | E26: 2 | G26: 1 | T26: 21,9,26 | U26: rapat manajemen | X26: 25
B27: 17,09,26 | C27: 1 | D27: 2 | F27: 1 | I27: 1 | U27: dr nilla | AA27: 1
B28: 18.9.26 | C28: 1 | D28: 2 | E28: 2 | I28: 2
B30: 20,09,2026 | C30: 0 | D30: 0 | E30: 0
B31: 21.09.2026 | C31: 0 | D31: 2 | E31: 1 | F31: 0 | G31: 0 | H31: 1 | J31: 0 | K31: 0
B32: 22,09,2026 | C32: 2 | D32: 2 | K32: 1
M33: Total | O33: =SUM(O10:O32) -> 0 | T33: Total | V33: =SUM(V10:V32) -> 124 | W33: =SUM(W10:W32) -> 20 | X33: =SUM(X10:X32) -> 278 | Y33: =SUM(Y10:Y32) -> 25 | Z33: =SUM(Z10:Z32) -> 40 | AA33: =SUM(AA10:AA32) -> 27
B34: 24,09,26 | C34: 1 | D34: 2 | F34: 1 | O34: 13000 | V34: 13000 | W34: 7500 | X34: 1540 | Y34: 10000 | Z34: 458
B35: 25,9,26 | C35: 1 | D35: 2 | E35: 1 | I35: 2
B36: 26,9,26 | O36: =O34*O33 -> 0 | P36: =SUM(P10:P32) -> 0 | Q36: =SUM(Q10:Q32) -> 0 | R36: =SUM(R10:R32) -> 0 | V36: =V34*V33 -> 1612000 | W36: =W34*W33 -> 150000 | X36: =X34*X33 -> 428120 | Y36: =Y34*Y33 -> 250000 | Z36: =Z34*Z33 -> 18320 | AA36: =AA34*AA33 -> 0
B37: 27,9,26 | C37: 0 | D37: 0 | E37: 0 | M37: total semua | O37: =O36+P39+Q39+R39 -> 0 | P37: 7500 | Q37: 1541 | R37: 458 | T37: total semua | V37: =V36+W36+X36+Y36+Z36 -> 2458440
B38: 28,09,2026 | D38: 2 | E38: 2 | H38: 1 | M38: harga snack | N38: 15000
P39: =P37*P36 -> 0 | Q39: =Q37*Q36 -> 0 | R39: =R37*R36 -> 0
B43: Total | C43: =SUM(C10:C42) -> 12 | D43: =SUM(D10:D42) -> 32 | E43: =SUM(E10:E42) -> 16 | F43: =SUM(F10:F42) -> 2 | G43: =SUM(G10:G42) -> 2 | H43: =SUM(H10:H42) -> 3 | I43: =SUM(I10:I42) -> 8 | J43: =SUM(J10:J42) -> 0 | K43: =SUM(K10:K42) -> 7
C44: 4500 | D44: 1916 | E44: 3500 | F44: 5403 | G44: 7300 | H44: 9943 | I44: 2000 | J44: 5000 | K44: 2902
C46: =C44*C43 -> 54000 | D46: =D44*D43 -> 61312 | E46: =E44*E43 -> 56000 | F46: =F44*F43 -> 10806 | G46: =G44*G43 -> 14600 | H46: =H44*H43 -> 29829 | I46: =I44*I43 -> 16000 | J46: =J44*J43 -> 0 | K46: =K44*K43 -> 20314
B48: total snack | C48: =C46+D46+E46+F46+G46+H46+I46+J46+K46+L36 -> 262861
B49: total makan | C49: =AJ5 -> 240000
C50: =C48+C49 -> 502861 | D50: realita
B51: total snack dan makan dalam 1bln | C51: =AH5 -> 8 | D51: =C51*50000 -> 400000 | E51: ekspektasi
...

Sheet pasien
B1: Rekapitulasi Makan Pasien
B2: RS ANNISA Tangerang
B5: Ruang : Vip
B6: Waktu Makan | C6: Tanggal | AH6: Total | AI6: Harga | AJ6: Jumlah | AM6: jumlah pasien | AO6: jml pasien | AR6: jmlh biaya makan pasien
C7: 1 | D7: 2 | E7: 3 | F7: 4 | G7: 5 | H7: 6 | I7: 7 | J7: 8 | K7: 9 | L7: 10 | M7: 11 | N7: 12 | O7: 13 | P7: 14 | Q7: 15 | R7: 16 | S7: 17 | T7: 18 | U7: 19 | V7: 20 | W7: 21 | X7: 22 | Y7: 23 | Z7: 24 | AA7: 25 | AB7: 26 | AC7: 27 | AD7: 28 | AE7: 29 | AF7: 30 | AG7: 31 | AO7: PU | AP7: =AH11+AH28+AH177 -> 0 | AR7: pu | AS7: =AJ11+AJ28+AJ177 -> 0
B8: Pagi | AH8: =SUM(C8:AG8) -> 0 | AI8: 29030 | AJ8: =AH8*AI8 -> 0 | AO8: kelas 1 | AP8: =AH20+AH37+AH46+AH71+AH96+AH123+AH150+AH186+AH213+AH240 -> 0 | AR8: kelas 1 | AS8: =AJ20+AJ37+AJ46+AJ71+AJ96+AJ123+AJ150+AJ186+AJ213+AJ240 -> 0
B9: Siang | AH9: =SUM(C9:AG9) -> 0 | AI9: 29030 | AJ9: =AH9*AI9 -> 0 | AO9: kelas 2 | AP9: =AH55+AH79+AH105+AH132+AH159+AH195+AH222+AH249 -> 0 | AR9: kelas 2 | AS9: =AJ55+AJ79+AJ105+AJ132+AJ159+AJ195+AJ222+AJ249 -> 0
B10: Malam | AH10: =SUM(C10:AG10) -> 0 | AI10: 29030 | AJ10: =AH10*AI10 -> 0 | AO10: kelas 3 | AP10: =AH63+AH87+AH114+AH141+AH168+AH204+AH231+AH258 -> 0 | AR10: kelas 3 | AS10: =AJ63+AJ87+AJ114+AJ141+AJ168+AJ204+AJ231+AJ258 -> 0
B11: Total | C11: =SUM(C8:C10) -> 0 | D11: =SUM(D8:D10) -> 0 | E11: =SUM(E8:E10) -> 0 | F11: =SUM(F8:F10) -> 0 | G11: =SUM(G8:G10) -> 0 | H11: =SUM(H8:H10) -> 0 | I11: =SUM(I8:I10) -> 0 | J11: =SUM(J8:J10) -> 0 | ... AJ11: =SUM(AJ8:AJ10) -> 0 | AL11: =SUM(C11:AG11) -> 0 | AM11: =SUM(C11:AG11) -> 0 | AP11: =SUM(AP7:AP10) -> 0 | AS11: =SUM(AS7:AS10) -> 0
AP12: =AL259 -> 0 | AS12: =AL303 -> 0
B13: Ruang : Kelas I
AP14: harga perporsi | AR14: =AS12/AP12 -> #DIV/0!
B15: Waktu Makan | C15: Tanggal | AH15: Total | AI15: Harga | AJ15: Jumlah
C16: 1 | D16: 2 | E16: 3 | F16: 4 | G16: 5 | H16: 6 | I16: 7 | J16: 8 | K16: 9 | L16: 10 | M16: 11 | N16: 12 | O16: 13 | P16: 14 | Q16: 15 | R16: 16 | S16: 17 | T16: 18 | U16: 19 | V16: 20 | W16: 21 | X16: 22 | Y16: 23 | Z16: 24 | AA16: 25 | AB16: 26 | AC16: 27 | AD16: 28 | AE16: 29 | AF16: 30 | AG16: 31
B17: Pagi | AH17: =SUM(C17:AG17) -> 0 | AI17: 19482 | AJ17: =AH17*AI17 -> 0
B18: Siang | AH18: =SUM(C18:AG18) -> 0 | AI18: 19482 | AJ18: =AH18*AI18 -> 0
B19: Malam | AH19: =SUM(C19:AG19) -> 0 | AI19: 19482 | AJ19: =AH19*AI19 -> 0
B20: Total | C20: =SUM(C17:C19) -> 0 | D20: =SUM(D17:D19) -> 0 | E20: =SUM(E17:E19) -> 0 | F20: =SUM(F17:F19) -> 0 | G20: =SUM(G17:G19) -> 0 | H20: =SUM(H17:H19) -> 0 | I20: =SUM(I17:I19) -> 0 | J20: =SUM(J17:J19) -> 0 | ... AJ20: =SUM(AJ17:AJ19) -> 0 | AL20: =SUM(C20:AG20) -> 0 | AM20: =SUM(C20:AG20) -> 0
B22: Ruang : Vip PU3
B23: Waktu Makan | C23: Tanggal | AH23: Total | AI23: Harga | AJ23: Jumlah
C24: 1 | D24: 2 | E24: 3 | F24: 4 | G24: 5 | H24: 6 | I24: 7 | J24: 8 | K24: 9 | L24: 10 | M24: 11 | N24: 12 | O24: 13 | P24: 14 | Q24: 15 | R24: 16 | S24: 17 | T24: 18 | U24: 19 | V24: 20 | W24: 21 | X24: 22 | Y24: 23 | Z24: 24 | AA24: 25 | AB24: 26 | AC24: 27 | AD24: 28 | AE24: 29 | AF24: 30 | AG24: 31
B25: Pagi | AH25: =SUM(C25:AG25) -> 0 | AI25: 29030 | AJ25: =AH25*AI25 -> 0
B26: Siang | AH26: =SUM(C26:AG26) -> 0 | AI26: 29030 | AJ26: =AH26*AI26 -> 0
B27: Malam | AH27: =SUM(C27:AG27) -> 0 | AI27: 29030 | AJ27: =AH27*AI27 -> 0
B28: Total | C28: =SUM(C25:C27) -> 0 | D28: =SUM(D25:D27) -> 0 | E28: =SUM(E25:E27) -> 0 | F28: =SUM(F25:F27) -> 0 | G28: =SUM(G25:G27) -> 0 | H28: =SUM(H25:H27) -> 0 | I28: =SUM(I25:I27) -> 0 | J28: =SUM(J25:J27) -> 0 | ... AJ28: =SUM(AJ25:AJ27) -> 0 | AL28: =SUM(C28:AG28) -> 0 | AM28: =SUM(C28:AG28) -> 0
B30: Ruang : Kelas I PU3
B32: Waktu Makan | C32: Tanggal | AH32: Total | AI32: Harga | AJ32: Jumlah
C33: 1 | D33: 2 | E33: 3 | F33: 4 | G33: 5 | H33: 6 | I33: 7 | J33: 8 | K33: 9 | L33: 10 | M33: 11 | N33: 12 | O33: 13 | P33: 14 | Q33: 15 | R33: 16 | S33: 17 | T33: 18 | U33: 19 | V33: 20 | W33: 21 | X33: 22 | Y33: 23 | Z33: 24 | AA33: 25 | AB33: 26 | AC33: 27 | AD33: 28 | AE33: 29 | AF33: 30 | AG33: 31
B34: Pagi | AH34: =SUM(C34:AG34) -> 0 | AI34: 19482 | AJ34: =AH34*AI34 -> 0
B35: Siang | AH35: =SUM(C35:AG35) -> 0 | AI35: 19482 | AJ35: =AH35*AI35 -> 0
B36: Malam | AH36: =SUM(C36:AG36) -> 0 | AI36: 19482 | AJ36: =AH36*AI36 -> 0
B37: Total | C37: =SUM(C34:C36) -> 0 | D37: =SUM(D34:D36) -> 0 | E37: =SUM(E34:E36) -> 0 | F37: =SUM(F34:F36) -> 0 | G37: =SUM(G34:G36) -> 0 | H37: =SUM(H34:H36) -> 0 | I37: =SUM(I34:I36) -> 0 | J37: =SUM(J34:J36) -> 0 | ... AJ37: =SUM(AJ34:AJ36) -> 0 | AL37: =SUM(C37:AG37) -> 0 | AM37: =SUM(C37:AG37) -> 0
B39: Ruang : Kelas I RPU 4
B41: Waktu Makan | C41: Tanggal | AH41: Total | AI41: Harga | AJ41: Jumlah
C42: 1 | D42: 2 | E42: 3 | F42: 4 | G42: 5 | H42: 6 | I42: 7 | J42: 8 | K42: 9 | L42: 10 | M42: 11 | N42: 12 | O42: 13 | P42: 14 | Q42: 15 | R42: 16 | S42: 17 | T42: 18 | U42: 19 | V42: 20 | W42: 21 | X42: 22 | Y42: 23 | Z42: 24 | AA42: 25 | AB42: 26 | AC42: 27 | AD42: 28 | AE42: 29 | AF42: 30 | AG42: 31
B43: Pagi | AH43: =SUM(C43:AG43) -> 0 | AI43: 19482 | AJ43: =AH43*AI43 -> 0
B44: Siang | AH44: =SUM(C44:AG44) -> 0 | AI44: 19482 | AJ44: =AH44*AI44 -> 0
B45: Malam | AH45: =SUM(C45:AG45) -> 0 | AI45: 19482 | AJ45: =AH45*AI45 -> 0
B46: Total | C46: =SUM(C43:C45) -> 0 | D46: =SUM(D43:D45) -> 0 | E46: =SUM(E43:E45) -> 0 | F46: =SUM(F43:F45) -> 0 | G46: =SUM(G43:G45) -> 0 | H46: =SUM(H43:H45) -> 0 | I46: =SUM(I43:I45) -> 0 | J46: =SUM(J43:J45) -> 0 | ... AJ46: =SUM(AJ43:AJ45) -> 0 | AL46: =SUM(C46:AG46) -> 0 | AM46: =SUM(C46:AG46) -> 0
B48: Ruang : Kelas II
...

Sheet dokter pagi
C3: CATATAN MAKAN DAN MINUMAN DOKTER | Q3: CATATAN MAKAN DAN MINUMAN DOKTER | AE3: CATATAN MAKAN DAN MINUMAN DOKTER | AS3: CATATAN MAKAN DAN MINUMAN DOKTER | BG3: CATATAN MAKAN DAN MINUMAN DOKTER | BU3: CATATAN MAKAN DAN MINUMAN DOKTER | CI3: CATATAN MAKAN DAN MINUMAN DOKTER
C5: senin | Q5: selasa | AE5: rabu | AS5: kamis | BG5: jumat | BU5: sabtu | CI5: minggu
B6: tgl dan petugas | C6: Nama dokter | D6: roti | E6: buah | F6: telur | G6: snack | H6: le mineral 600 | I6: kopi KA | J6: kopi 3 in 1 | K6: pocari | L6: buavita | M6: the | N6: oxy | P6: tgl dan petugas | Q6: Nama dokter | R6: roti | S6: buah | T6: telur | U6: snack | V6: le mineral 600 | W6: kopi KA | X6: kopi 3 in 1 | Y6: pocari | Z6: buavita | AA6: the | AB6: oxy | AD6: tgl dan petugas | AE6: Nama dokter | AF6: roti | AG6: buah | AH6: telur | AI6: snack | AJ6: le mineral 600 | AK6: kopi KA | AL6: kopi 3 in 1 | AM6: pocari | AN6: buavita | AO6: the | AP6: oxy | AR6: tgl dan petugas | AS6: Nama dokter | AT6: roti | AU6: buah | AV6: telur | AW6: snack | AX6: le mineral 600 | AY6: kopi KA | AZ6: kopi 3 in 1 | BA6: pocari | BB6: buavita | BC6: the | BD6: oxy | BF6: tgl dan petugas | BG6: Nama dokter | BH6: roti | BI6: buah | BJ6: telur | BK6: snack | BL6: le mineral 600 | BM6: kopi KA | BN6: kopi 3 in 1 | BO6: pocari | BP6: buavita | BQ6: the | BR6: oxy | BT6: tgl dan petugas | BU6: Nama dokter | BV6: roti | BW6: buah | BX6: telur | BY6: snack | BZ6: le mineral 600 | CA6: kopi KA | CB6: kopi 3 in 1 | CC6: pocari | CD6: buavita | CE6: the | CF6: oxy | CH6: tgl dan petugas | CI6: Nama dokter | CJ6: roti | CK6: buah | CL6: telur | CM6: snack | CN6: le mineral 600 | CO6: kopi KA | CP6: kopi 3 in 1 | CQ6: pocari | CR6: buavita | CS6: the | CT6: oxy
B8: 7.9.26 | C8: dr denok | E8: 1 | H8: 1 | J8: 1 | P8: 1,9,2026 | Q8: dr ari m | U8: 1 | V8: 1 | AD8: 02.09.2026 | AE8: dr. ari mulyani | AI8: 1 | AJ8: 1 | AR8: 03.09.26 | AS8: dr.ari mulyni | AW8: 1 | AX8: 1 | BF8: 4,09,26 | BG8: dr lola | BI8: 1 | BL8: 1 | BT8: 05,09,2026 | BU8: dr asseane | BW8: 1 | BZ8: 1 | CH8: titik | CI8: drg rosalina | CM8: 1 | CN8: 1
B9: lista | C9: dr reza | G9: 1 | H9: 1 | P9: titk | Q9: dr amin | U9: 1 | V9: 1 | AE9: dr. denok | AG9: 1 | AJ9: 1 | AS9: dr.alvin | AW9: 1 | AX9: 1 | BF9: ridwan | BG9: dr irawati | BI9: 2 | BL9: 1 | BT9: elina | BU9: dr minanul | BW9: 1 | BZ9: 1 | CH9: 6,9,26 | CI9: dr. Farida | CK9: 1 | CN9: 1 | CO9: 1
C10: dr asseane | E10: 1 | H10: 1 | Q10: dr denok | S10: 1 | V10: 1 | AE10: dr. reza akbar. | AI10: 0 | AJ10: 0 | AS10: dr.yasminda | AW10: 1 | AX10: 1 | BG10: dr apul | BI10: 1 | BL10: 1 | BU10: dr apul dina | BW10: 1 | BZ10: 1 | CI10: dr. Pinsky | CK10: 2 | CN10: 1 | CO10: 1
C11: dr riko | G11: 1 | H11: 1 | Q11: dr yasminda | S11: 1 | V11: 1 | AE11: dr. yasminda | AG11: 1 | AJ11: 1 | AS11: dr.aseanne | AW11: 1 | AX11: 1 | BG11: dr agusnidar | BI11: 1 | BL11: 1 | BU11: dr agusnidar | BW11: 1 | BZ11: 1 | CI11: dr. Hafifah | CM11: 0
C12: dr chintya | Q12: dr alvin | U12: 1 | V12: 1 | AE12: dr. aseane | AG12: 1 | AJ12: 1 | AS12: dr.minanul | AU12: 1 | AX12: 1 | BG12: dr isnada | BK12: 1 | BL12: 1 | BU12: dr vini | BZ12: 0 | CI12: dr. Rezky | CM12: 1 | CN12: 1
C13: dr anggita | G13: 1 | H13: 1 | Q13: dr ane | S13: 1 | V13: 1 | AE13: dr. riko | AI13: 1 | AJ13: 1 | AS13: dr.apuldina | AU13: 1 | AX13: 1 | BG13: dr estu | BK13: 1 | BL13: 1 | BU13: dr ade | BY13: 1 | BZ13: 1 | CI13: drg. Redho | CK13: 1 | CM13: 1 | CS13: 1
C14: dr yenny | G14: 1 | H14: 1 | Q14: dr minan | S14: 1 | V14: 1 | AE14: dr. annastasia | AI14: 1 | AJ14: 1 | AS14: dr.rosalina | AW14: 1 | AX14: 1 | BG14: dr sila | BJ14: 3 | BL14: 1 | BU14: dr usep | BY14: 1 | BZ14: 1 | CA14: 1 | CI14: drg. Yanti | CM14: 1 | CN14: 1
C15: dr redho | E15: 1 | H15: 1 | M15: 1 | Q15: dr apuldina | S15: 1 | V15: 1 | AE15: dr. yenny | AI15: 0 | AJ15: 0 | AS15: dr.a.ismail | AW15: 1 | AX15: 1 | BG15: dr saeful | BL15: 2 | BO15: 1 | BU15: dr dwiyana | BZ15: 0 | CI15: dr afrianti | CM15: 1 | CN15: 1
C16: dr sila | F16: 1 | H16: 1 | I16: 1 | Q16: dr agusnidar | S16: 1 | V16: 1 | AE16: dr. sila | AH16: 1 | AJ16: 1 | AK16: 1 | AS16: dr.anastasia | AW16: 1 | AX16: 1 | BG16: dr brilian | BI16: 1 | BL16: 1 | BU16: dr nabila | BY16: 1 | BZ16: 1 | CI16: dr wisuda | CK16: 1 | CN16: 1
C17: dr estu | G17: 1 | H17: 1 | Q17: dr brilian | V17: 0 | AE17: dr. vini | AI17: 1 | AJ17: 1 | AS17: dr.retno | AW17: 1 | AX17: 1 | BG17: dr feriyanto | BJ17: 3 | BL17: 1 | BU17: dr redho | BW17: 1 | BZ17: 1 | CI17: dr.ade widyastuti | CM17: 1 | CN17: 1
C18: dr helda | E18: 1 | H18: 1 | Q18: dr saiful | V18: 2 | Y18: 2 | AE18: dr. estu | AI18: 1 | AJ18: 1 | AS18: dr.vini | AW18: 1 | AX18: 1 | BG18: dr arie | BI18: 1 | BL18: 1 | BU18: dr estu | BY18: 1 | BZ18: 1 | CI18: dr.anggita | CM18: 1 | CN18: 1 | CS18: 1
C19: dr farida | E19: 1 | H19: 1 | I19: 1 | Q19: dr usep | U19: 1 | V19: 1 | W19: 1 | AE19: dr. helda | AG19: 1 | AJ19: 1 | AS19: dr.estu | AW19: 1 | AX19: 1 | BG19: dr vina | BI19: 1 | BL19: 1 | BU19: dr isnada | BY19: 1 | BZ19: 1 | CI19: dr fauzi | CM19: 1 | CN19: 1
C20: dr saiful | H20: 4 | K20: 2 | Q20: dr retno | U20: 1 | V20: 1 | AE20: dr. melfa | AI20: 1 | AJ20: 1 | AS20: dr.ferianto | AV20: 1 | AX20: 1 | AY20: 1 | BG20: dr ryant | BK20: 1 | BL20: 1 | BU20: dr ari | BY20: 0 | BZ20: 0 | CI20: dr.puti | CM20: 0 | CN20: 0
C21: dr tintin | E21: 1 | G21: 1 | H21: 2 | Q21: dr yeni | U21: 1 | V21: 1 | AE21: dr. venasius | AI21: 1 | AJ21: 1 | AS21: dr.puti | AW21: 1 | AX21: 1 | BG21: dr lisa | BK21: 1 | BL21: 1 | BU21: dr karinca | BY21: 1 | BZ21: 1 | CI21: dr maya | CK21: 1 | CL21: 1 | CN21: 1 | CO21: 1
C22: dr susi | E22: 1 | H22: 1 | Q22: dr sila | S22: 1 | V22: 1 | W22: 1 | AE22: dr. herman s | AI22: 1 | AJ22: 1 | AS22: dr.karinca | AW22: 1 | AX22: 1 | BG22: dr ari mulyani | BK22: 1 | BL22: 1 | BU22: dr amarullah | BW22: 1 | BZ22: 1 | CI22: dr wicaksono | CM22: 1 | CN22: 1
C23: dr irawati | Q23: dr redho | S23: 1 | V23: 1 | AA23: 1 | AE23: dr. lola | AG23: 1 | AJ23: 1 | AK23: 2 | AS23: dr.farida | AU23: 1 | AX23: 1 | BG23: dr amin | BK23: 1 | BL23: 1 | BU23: dr amin | BW23: 1 | BY23: 1 | BZ23: 2 | CI23: dr.rahma | CM23: 0 | CN23: 0
C24: dr arie asnafi | E24: 1 | H24: 1 | M24: 1 | Q24: dr feriyanto | T24: 3 | V24: 1 | W24: 1 | AE24: dr. pinsky | AG24: 1 | AJ24: 1 | AK24: 1 | AS24: drsaiful | AX24: 1 | BG24: dr susi | BI24: 1 | BL24: 1 | BU24: dr herman suryatama | BZ24: 0 | CI24: dr tri | CN24: 0
C25: dr venasius | G25: 1 | H25: 1 | Q25: dr rizaldi | T25: 3 | V25: 1 | W25: 1 | AE25: dr. hamidah | AI25: 1 | AJ25: 1 | AK25: 1 | AS25: dr.usep | AW25: 1 | AX25: 1 | BG25: dr aseane | BI25: 1 | BL25: 1 | BU25: dr susi | BW25: 1 | BZ25: 1 | CI25: dr ruangan pagi | CM25: 2
C26: lounge dokter | K26: 3 | L26: 3 | Q26: dr amar | S26: 1 | V26: 1 | AE26: dr. susi | AG26: 2 | AJ26: 2 | AS26: dr.dwiyana | AX26: 1 | BG26: dr minan | BI26: 1 | BL26: 1 | BU26: dr yelly | BY26: 1 | BZ26: 1 | CI26: dr.umum pagi | CM26: 3
C27: dr umum pagi | G27: 3 | Q27: dr putri | S27: 1 | V27: 1 | W27: 1 | AE27: dr. irawati | AG27: 2 | AJ27: 2 | AS27: dr.lola | AU27: 1 | AX27: 1 | BG27: dr maechel | BJ27: 3 | BL27: 1 | BU27: dr melfa | BY27: 0 | BZ27: 0
C28: dr ruangan pagi | G28: 3 | Q28: dr pandu | V28: 0 | AE28: dr. arie asnafi | AG28: 1 | AJ28: 1 | AS28: dr.tintin | AW28: 1 | AX28: 1 | BG28: dr amar | BI28: 1 | BL28: 1 | BU28: dr irawati | BW28: 1 | BZ28: 1 | CH28: 13.09.26 | CI28: drg rosalina | CM28: 1 | CN28: 1
C29: dr ismail | G29: 1 | H29: 1 | Q29: dr tin tin | U29: 1 | V29: 1 | AE29: louge dokter | AM29: 5 | AN29: 5 | AS29: dr.andy n | AW29: 1 | AX29: 1 | AZ29: 1 | BG29: dr visto | BK29: 1 | BL29: 1 | BU29: dr arie asnafi | BW29: 1 | BZ29: 1 | CB29: 1 | CH29: lista | CI29: dr. Farida | CK29: 1 | CN29: 1 | CO29: 1
C30: dr agusnidar | E30: 1 | H30: 1 | Q30: dr andi | S30: 1 | V30: 1 | X30: 1 | AE30: dr ike | AS30: dr,.erika | AW30: 1 | AX30: 1 | BG30: dr ruangan | BK30: 2 | BU30: dr ilhandi | BZ30: 1 | CE30: 1 | CI30: dr. Pinsky | CK30: 2 | CN30: 1 | CO30: 1
C31: dr herman s | Q31: dr maya | S31: 1 | T31: 2 | V31: 1 | W31: 1 | AE31: dr marina | AG31: 1 | AI31: 1 | AJ31: 1 | AS31: dr,susi | AU31: 1 | AX31: 1 | BG31: dr umum | BK31: 3 | BU31: dr edi budi | BW31: 1 | BZ31: 1 | CI31: dr. Hafifah | CM31: 0
C32: dr lola | Q32: dr lola | S32: 2 | V32: 2 | W32: 2 | AE32: dr umum pagi | AI32: 3 | AS32: dr.melfa | AW32: 1 | AX32: 1 | BU32: dr.wicaksono | BY32: 1 | BZ32: 1 | CI32: dr. Rezky | CM32: 1 | CN32: 1
C33: dr.reihan | E33: 1 | H33: 1 | Q33: dr erika | S33: 2 | V33: 2 | AE33: dr ruangan pagi | AI33: 3 | AS33: dr.irawati | AU33: 1 | AX33: 1 | BU33: dr pinksy | BW33: 2 | BZ33: 1 | CA33: 1 | CI33: drg. Redho | CK33: 1 | CM33: 1 | CS33: 1
C34: dr.anita | E34: 2 | G34: 2 | H34: 2 | Q34: dr yely | U34: 2 | V34: 2 | AE34: dr.ruangan siang | AI34: 3 | AS34: dr.ilhandi | AX34: 1 | BC34: 1 | BF34: 11,9,26 | BG34: dr lola | BI34: 1 | BL34: 1 | BU34: dr maya | BW34: 1 | BX34: 2 | BZ34: 1 | CA34: 1 | CI34: drg. Yanti | CM34: 1 | CN34: 1
Q35: dr irawati | S35: 2 | V35: 2 | AE35: dr.umum siang | AG35: 1 | AI35: 2 | AS35: dr.amar | AU35: 1 | AX35: 1 | BF35: yurlis | BG35: dr irawati | BI35: 2 | BL35: 1 | BU35: dr michael | BY35: 0 | BZ35: 0 | CI35: dr afrianti | CM35: 1 | CN35: 1
Q36: dr ari a | T36: 3 | V36: 1 | AA36: 1 | AE36: dr.phima | AI36: 1 | AJ36: 1 | AS36: dr.minanul | AU36: 1 | BG36: dr apul | BI36: 1 | BL36: 1 | BU36: dr arif | BW36: 1 | BY36: 1 | BZ36: 1 | CI36: dr wisuda | CK36: 1 | CN36: 1
B37: 14.09.26 | C37: dr denok | E37: 1 | H37: 1 | J37: 1 | Q37: dr ilhandi | V37: 1 | AA37: 1 | AE37: dr.arif | AG37: 1 | AI37: 1 | AJ37: 1 | AS37: dr umum pagi | AW37: 3 | BG37: dr agusnidar | BI37: 1 | BL37: 1 | BU37: dr marina | BZ37: 0 | CI37: dr.ade widyastuti | CM37: 1 | CN37: 1
B38: lista | C38: dr reza | G38: 1 | H38: 1 | Q38: dr ike | S38: 1 | U38: 1 | V38: 1 | AE38: dr nienie | AI38: 1 | AJ38: 1 | AS38: dr ruangan pagi | AW38: 3 | BG38: dr isnada | BK38: 1 | BL38: 1 | BU38: dr ruangan pagi | BY38: 3 | CI38: dr.anggita | CM38: 1 | CN38: 1 | CS38: 1
C39: dr asseane | E39: 1 | H39: 1 | Q39: dr arif | S39: 1 | U39: 1 | V39: 1 | AS39: dr.ruangan siang | AW39: 3 | BG39: dr estu | BK39: 1 | BL39: 1 | BU39: dr umum pagi | BY39: 3 | CI39: dr fauzi | CM39: 1 | CN39: 1
C40: dr riko | G40: 1 | H40: 1 | Q40: dr marina | S40: 1 | U40: 1 | V40: 1 | AS40: dr.umum siang | AW40: 2 | BG40: dr sila | BJ40: 3 | BL40: 1 | BU40: lounge dokter | CC40: 5 | CD40: 5 | CI40: dr.puti | CM40: 0 | CN40: 0
C41: dr chintya | Q41: dr umum pagi | U41: 3 | AD41: 09.09.2026 | AE41: dr. ari mulyani | BG41: dr saeful | BL41: 2 | BO41: 1 | BU41: dr.lisa | BY41: 1 | BZ41: 1 | CI41: dr maya | CK41: 1 | CL41: 1 | CN41: 1 | CO41: 1
C42: dr anggita | G42: 1 | H42: 1 | Q42: dr ruangan pagi | U42: 3 | AE42: dr. denok | BG42: dr brilian | BI42: 1 | BL42: 1 | BU42: dr.anggraeni | BZ42: 0 | CI42: dr wicaksono | CM42: 1 | CN42: 1
C43: dr yenny | G43: 1 | H43: 1 | Q43: LOUNGE DKR | Y43: 3 | Z43: 3 | AE43: dr. reza akbar. | AR43: 10,09,2026 | AS43: dr.ari mulyni | AW43: 1 | AX43: 1 | BG43: dr feriyanto | BJ43: 3 | BL43: 1 | BU43: dr.isnada | BY43: 1 | BZ43: 1 | CI43: dr.rahma | CM43: 0 | CN43: 0
C44: dr redho | E44: 1 | H44: 1 | M44: 1 | Q44: dr viny | U44: 2 | V44: 2 | AE44: dr. yasminda | AR44: elina | AS44: dr.alvin | AW44: 1 | AX44: 1 | BG44: dr arie | BI44: 1 | BL44: 1 | BU44: dr.martha | BV44: 1 | BW44: 1 | BZ44: 1 | CE44: 1 | CI44: dr tri | CN44: 0
...

Sheet dokter siang
C3: CATATAN MAKAN DAN MINUMAN DOKTER | Q3: CATATAN MAKAN DAN MINUMAN DOKTER | AE3: CATATAN MAKAN DAN MINUMAN DOKTER | AS3: CATATAN MAKAN DAN MINUMAN DOKTER | BG3: CATATAN MAKAN DAN MINUMAN DOKTER | BU3: CATATAN MAKAN DAN MINUMAN DOKTER | CI3: CATATAN MAKAN DAN MINUMAN DOKTER
C5: senin | Q5: selasa | AE5: rabu | AS5: kamis | BG5: jumat | BU5: sabtu | CI5: minggu
B6: tgl dan petugas | C6: Nama dokter | D6: roti | E6: buah | F6: telur | G6: snack | H6: le mineral 600 | I6: kopi KA | J6: kopi 3 in 1 | K6: pocari | L6: buavita | M6: the | N6: oxy | P6: tgl dan petugas | Q6: Nama dokter | R6: roti | S6: buah | T6: telur | U6: snack | V6: le mineral 600 | W6: kopi KA | X6: kopi 3 in 1 | Y6: pocari | Z6: buavita | AA6: the | AB6: oxy | AD6: tgl dan petugas | AE6: Nama dokter | AF6: roti | AG6: buah | AH6: telur | AI6: snack | AJ6: le mineral 600 | AK6: kopi KA | AL6: kopi 3 in 1 | AM6: pocari | AN6: buavita | AO6: the | AP6: oxy | AR6: tgl dan petugas | AS6: Nama dokter | AT6: roti | AU6: buah | AV6: telur | AW6: snack | AX6: le mineral 600 | AY6: kopi KA | AZ6: kopi 3 in 1 | BA6: pocari | BB6: buavita | BC6: the | BD6: oxy | BF6: tgl dan petugas | BG6: Nama dokter | BH6: roti | BI6: buah | BJ6: telur | BK6: snack | BL6: le mineral 600 | BM6: kopi KA | BN6: kopi 3 in 1 | BO6: pocari | BP6: buavita | BQ6: the | BR6: oxy | BT6: tgl dan petugas | BU6: Nama dokter | BV6: roti | BW6: buah | BX6: telur | BY6: snack | BZ6: le mineral 600 | CA6: kopi KA | CB6: kopi 3 in 1 | CC6: pocari | CD6: buavita | CE6: the | CF6: oxy | CH6: tgl dan petugas | CI6: Nama dokter | CJ6: roti | CK6: buah | CL6: telur | CM6: snack | CN6: le mineral 600 | CO6: kopi KA | CP6: kopi 3 in 1 | CQ6: pocari | CR6: buavita | CS6: the | CT6: oxy
B8: 07.09.26 | C8: dr amin husni | G8: 1 | H8: 1 | P8: 1,9,2026 | Q8: rahma | V8: 0 | AD8: 02.09.2026 | AE8: dr. amin husni | AI8: 1 | AJ8: 1 | AR8: 03.09.26 | AS8: dr maya | AU8: 1 | AV8: 2 | AX8: 1 | AY8: 1 | BF8: 4,9,26 | BG8: dr arif budiman | BI8: 1 | BL8: 1 | BM8: 1 | BT8: 05.09.2026 | BU8: dr amin | BW8: 1 | BZ8: 1 | CH8: titik | CI8: dr umum siang | CM8: 3
B9: lista | C9: dr ari mulyani | G9: 1 | H9: 1 | P9: titik | Q9: dr agusnidar | S9: 1 | V9: 1 | AE9: dr. arif budiman | AG9: 1 | AJ9: 1 | AS9: dr pinski | AU9: 2 | AX9: 1 | AY9: 1 | BF9: ridwan | BG9: dr saka | BK9: 1 | BL9: 1 | BT9: elina | BU9: dr khalif | BW9: 0 | CH9: 6,9,26 | CI9: dr ruangan siang | CM9: 2
C10: dr arif budiman | E10: 1 | H10: 1 | Q10: dr marina | S10: 1 | U10: 1 | V10: 1 | AE10: dr. Michael | AJ10: 2 | AS10: dr hafifah | AU10: 1 | AX10: 1 | BG10: dr michael | BL10: 1 | BU10: dr haris | BW10: 1 | BZ10: 1 | CI10: dr umum malam | CJ10: 3
C11: dr nila | H11: 1 | Q11: dr minan | S11: 1 | V11: 1 | AE11: dr. wisuda | AG11: 1 | AJ11: 1 | AS11: dr agusnidar | AU11: 1 | AX11: 1 | BG11: dr minan | BI11: 1 | BL11: 1 | BU11: dr.ruangan siang | BY11: 3 | CI11: dr ruangan malam | CJ11: 2
C12: dr saka | E12: 1 | H12: 1 | Q12: dr martha | R12: 1 | S12: 1 | V12: 1 | AE12: dr. ledia | AF12: 1 | AJ12: 1 | AS12: dr marina | AU12: 1 | AW12: 1 | AX12: 1 | BG12: dr wisuda | BI12: 1 | BL12: 1 | BU12: dr.umum siang | BY12: 3
C13: dr michael | H13: 2 | Q13: dr haris | S13: 1 | V13: 1 | AE13: dr. agusnidar | AG13: 1 | AJ13: 1 | AS13: dr a. ismail | AW13: 1 | AX13: 1 | BG13: dr ledia | BH13: 1 | BL13: 1 | BU13: dr.ruangan malam | BV13: 2 | CH13: 13,09,26 | CI13: dr umum siang | CM13: 3
C14: dr minanul | E14: 1 | H14: 1 | AE14: dr. edwin | AI14: 1 | AJ14: 1 | AS14: dr martha | AU14: 1 | AX14: 1 | BG14: dr agusnidar | BI14: 1 | BL14: 1 | BU14: dr.umum malam | BV14: 3 | CH14: lista | CI14: dr ruangan siang | CM14: 2
C15: dr wisuda | E15: 1 | H15: 1 | Q15: dr margareta | R15: 1 | V15: 1 | AE15: dr. ismail | AI15: 1 | AJ15: 1 | AS15: dr haris | AU15: 1 | AX15: 1 | BG15: dr rosalina | BK15: 1 | BL15: 1 | BU15: dr fauzi | BV15: 1 | BZ15: 1 | CI15: dr umum malam | CJ15: 3
C16: dr agusnidar | AE16: dr. rita | AI16: 1 | AJ16: 1 | AS16: dr ida farida | AU16: 1 | AV16: 1 | AX16: 1 | BG16: dr edwin | BK16: 1 | BL16: 1 | BU16: dr apul | BW16: 1 | BZ16: 1 | CI16: dr ruangan malam | CJ16: 2
C17: dr hafifah | E17: 1 | G17: 1 | H17: 2 | Q17: dr m fauzi | V17: 0 | AE17: dr. sitti andi | AG17: 1 | AJ17: 1 | AS17: dr margareta | AV17: 1 | AX17: 1 | BG17: dr ismail | BK17: 1 | BL17: 1
C18: dr ilhandi | H18: 1 | M18: 1 | Q18: dr yenny | U18: 1 | V18: 1 | AE18: dr. jans | AG18: 1 | AJ18: 1 | AS18: dr melfa | AW18: 1 | AX18: 1 | BG18: dr retno | BK18: 1 | BL18: 1 | CH18: 20,09,2026 | CI18: dr umum siang | CM18: 3
C19: dr retno | E19: 1 | H19: 1 | Q19: dr lisa | U19: 1 | V19: 1 | AE19: dr. feliana | AI19: 1 | AJ19: 1 | AS19: dr wisuda | AU19: 1 | AX19: 1 | BG19: dr sitti andi | BI19: 2 | BL19: 1 | BT19: titik | BU19: dr amin | BW19: 1 | BZ19: 1 | CH19: ismi | CI19: dr ruangan siang | CM19: 2
C20: dr rezky | G20: 1 | H20: 1 | Q20: dr retno | U20: 1 | V20: 1 | AE20: dr. Harris | AG20: 1 | AJ20: 1 | AS20: dr minan | AU20: 1 | AX20: 1 | BG20: dr andrian | BK20: 1 | BL20: 1 | BT20: 12,9,26 | BU20: dr khalif | BW20: 0 | BZ20: 0 | CI20: dr umum malam | CJ20: 3
C21: dr feliana | G21: 1 | H21: 1 | Q21: dr rezky | U21: 1 | V21: 1 | AE21: dr. martha | AF21: 1 | AG21: 1 | AJ21: 1 | AS21: dr yenni | AW21: 1 | AX21: 1 | BG21: dr feliana | BK21: 1 | BL21: 1 | BU21: dr haris | BW21: 1 | BZ21: 1 | CI21: dr ruangan malam | CJ21: 2
C22: dr harris | E22: 1 | H22: 1 | Q22: dr wicaksono | U22: 1 | V22: 1 | AE22: dr. isnada | AI22: 1 | AJ22: 1 | AS22: dr nila | AX22: 1 | BG22: dr harris | BI22: 1 | BL22: 1 | BU22: dr.ruangan siang | BY22: 3
C23: dr martha | D23: 1 | E23: 1 | H23: 1 | Q23: dr erika | S23: 1 | V23: 1 | AE23: dr. rezaldi | AH23: 1 | AJ23: 1 | AK23: 1 | AS23: dr arfianti | AW23: 1 | AX23: 1 | BG23: dr karinca | BK23: 1 | BL23: 1 | BU23: dr.umum siang | BY23: 3
C24: dr karinca | G24: 1 | H24: 1 | Q24: dr ruangan siang | U24: 3 | AE24: dr. astri | AI24: 1 | AJ24: 1 | AS24: dr anggreani | AW24: 1 | AX24: 1 | BG24: dr helda | BK24: 1 | BL24: 1 | BU24: dr.ruangan malam | BV24: 2 | CH24: 27,9,26 | CI24: dr umum siang | CM24: 3
C25: dr usep | G25: 1 | H25: 1 | Q25: dr umum siang | U25: 3 | AE25: dr. fauzi | AF25: 1 | AJ25: 1 | AS25: dr harris | AX25: 1 | BG25: dr amar | BI25: 1 | BL25: 1 | BU25: dr.umum malam | BV25: 3 | CH25: titik | CI25: dr ruangan siang | CM25: 2
A26: . | C26: dr dwiyana | H26: 1 | L26: 1 | Q26: dr.arfianti | R26: 1 | V26: 1 | AE26: dr. Pras | AG26: 1 | AJ26: 1 | AS26: dr erika | AW26: 1 | AX26: 1 | BG26: dr khalif | BK26: 1 | BL26: 1 | BU26: dr fauzi | BV26: 1 | BZ26: 1 | CI26: dr umum malam | CJ26: 3
A27: . | C27: dr pinsky | E27: 2 | H27: 1 | I27: 1 | Q27: dr rungan malem | R27: 2 | AE27: dr. maya | AG27: 1 | AH27: 1 | AJ27: 1 | AK27: 1 | AS27: dr m fauzi | AX27: 1 | BG27: dr fauzi | BK27: 1 | BL27: 1 | BU27: dr apul | BW27: 1 | BZ27: 1 | CI27: dr ruangan malam | CJ27: 2
C28: dr maya | E28: 1 | F28: 1 | H28: 1 | I28: 1 | Q28: dr umum malem | R28: 3 | AE28: dr. ilham | AF28: 1 | AJ28: 1 | AK28: 1 | AS28: dr. irawati | AU28: 1 | AX28: 1 | BG28: dr venansius | BH28: 1 | BL28: 1
C29: dr ilham | D29: 1 | H29: 1 | I29: 1 | AE29: dr. pinsky | AG29: 1 | AJ29: 1 | AK29: 1 | AS29: dr lisa | AX29: 1 | BG29: dr edi | BI29: 1 | BL29: 1 | BT29: 19,9,26 | BU29: dr ndrian | BY29: 1 | BZ29: 1 | CH29: Total | CJ29: =SUM(CJ8:CJ28) -> 20 | CK29: =SUM(CK8:CK28) -> 0 | CL29: =SUM(CL8:CL28) -> 0 | CM29: =SUM(CM8:CM28) -> 20 | CN29: =SUM(CN8:CN28) -> 0 | CO29: =SUM(CO8:CO28) -> 0 | CP29: =SUM(CP8:CP28) -> 0 | CQ29: =SUM(CQ8:CQ28) -> 0 | ... CT29: =SUM(CT8:CT28) -> 0
C30: dr wicaksono | D30: 1 | H30: 1 | P30: 8,9,26 | Q30: rahma | V30: 0 | AE30: dr. rita | AI30: 1 | AJ30: 1 | AS30: dr retno | AW30: 1 | AX30: 1 | BG30: dr pinsky | BI30: 1 | BL30: 1 | BM30: 1 | BT30: BAYU | BU30: dr amin | BW30: 1 | BZ30: 1 | CJ30: 7500 | CK30: 5833 | CL30: 1562 | CM30: 9000 | CN30: 1958 | CO30: 1400 | CP30: 1310 | CQ30: 5403 | CR30: 7300 | CS30: 774 | CT30: 8467
C31: dr rina | G31: 1 | H31: 1 | P31: titik | Q31: dr agusnidar | S31: 1 | V31: 1 | AE31: dr. susi | AI31: 1 | AJ31: 1 | AS31: dr yanti | AW31: 1 | AX31: 1 | BG31: dr maya | BI31: 1 | BL31: 1 | BM31: 1 | BU31: dr fauzi | BY31: 1 | BZ31: 1 | CI31: Total semua | CJ31: =CJ29*CJ30 -> 150000 | CK31: =CK29*CK30 -> 0 | CL31: =CL29*CL30 -> 0 | CM31: =CM29*CM30 -> 180000 | CN31: =CN29*CN30 -> 0 | CO31: =CO29*CO30 -> 0 | CP31: =CP29*CP30 -> 0 | CQ31: =CQ29*CQ30 -> 0 | ... CT31: =CT29*CT30 -> 0
C32: dr yelly | G32: 1 | H32: 1 | Q32: dr marina | S32: 1 | U32: 1 | V32: 1 | AE32: dr. melfa | AI32: 1 | AJ32: 1 | AS32: dr puti | AW32: 1 | AX32: 1 | BG32: dr ilham | BH32: 1 | BL32: 1 | BM32: 1 | BU32: dr harris | BW32: 1 | BZ32: 1 | CI32: total semua | CJ32: =CJ31+CK31+CL31+CM31+CN31+CO31+CP31+CQ31+CR31+CS31+CT31 -> 330000
C33: dr melfa | G33: 1 | H33: 1 | Q33: dr minan | S33: 1 | V33: 1 | AE33: dr. irawati | BG33: dr rina | BK33: 1 | BL33: 1 | BU33: dr yanti | BY33: 1 | BZ33: 1 | CI33: total snack | CJ33: =CJ29+CK29+CL29+CM29+CQ29+CR29+CT29 -> 40 | CK33: gab roti, buah telur snack, pocari buah vita
C34: dr umum siang | G34: 3 | Q34: dr martha | R34: 1 | S34: 1 | V34: 1 | AE34: dr. hafifah | AI34: 1 | AJ34: 1 | AR34: 10.09.2026 | AS34: dr maya | AU34: 1 | AV34: 2 | AX34: 1 | AY34: 1 | BG34: dr yelly | BK34: 1 | BL34: 1 | BN34: 1 | BU34: dr arif | BW34: 1 | BY34: 1 | BZ34: 1 | CP34: =CO31+CP31+CQ31+CR31+CS31+CT31 -> 0
C35: dr ruangan siang | G35: 3 | Q35: dr haris | S35: 1 | V35: 1 | AE35: dr. ilhandi | AJ35: 1 | AO35: 1 | AR35: elina | AS35: dr pinski | AU35: 2 | AX35: 1 | AY35: 1 | BG35: dr melfa | BK35: 1 | BL35: 1 | BU35: dr rungan malam | BY35: 3 | BZ35: 1 | CS35: =CP34+J156+X122+AL144+AZ128+BN176+CB80 -> 98506
C36: dr ruangan malam | D36: 2 | AE36: dr.umum malam | AF36: 3 | AS36: dr hafifah | AU36: 1 | AX36: 1 | BG36: dr ida farida | BI36: 1 | BJ36: 1 | BL36: 1 | BM36: 1 | BU36: dr umum malam | BY36: 3 | BZ36: 1
C37: dr umum malam | D37: 3 | Q37: dr margareta | R37: 1 | V37: 1 | AE37: dr.ruangan malam | AF37: 2 | AS37: dr agusnidar | AU37: 1 | AX37: 1 | BG37: dr irawati | BI37: 1 | BL37: 1
C38: dr.marina | E38: 1 | G38: 1 | H38: 1 | AS38: dr marina | AU38: 1 | AW38: 1 | AX38: 1 | BG38: dr ilhandi | BL38: 1 | BQ38: 1 | BT38: 46291 | BU38: dr ndrian | BY38: 1 | BZ38: 1
Q39: dr m fauzi | V39: 0 | AS39: dr a. ismail | AW39: 1 | AX39: 1 | BG39: dokter umum | BH39: 3 | BT39: elina | BU39: dr amin | BW39: 1 | BZ39: 1
B40: 14,09,26 | C40: dr amin husni | G40: 1 | H40: 1 | Q40: dr yenny | U40: 1 | V40: 1 | AS40: dr martha | AU40: 1 | AX40: 1 | BG40: dokter jaga | BH40: 2 | BU40: dr fauzi | BY40: 1 | BZ40: 1
B41: lista | C41: dr ari mulyani | G41: 1 | H41: 1 | Q41: dr lisa | U41: 1 | V41: 1 | AE41: dr. amin husni | AS41: dr haris | AU41: 1 | AX41: 1 | BU41: dr harris | BW41: 1 | BZ41: 1
C42: dr arif budiman | E42: 1 | H42: 1 | Q42: dr retno | U42: 1 | V42: 1 | AE42: dr. arif budiman | AS42: dr ida farida | AU42: 1 | AV42: 1 | AX42: 1 | BU42: dr yanti | BW42: 1 | BZ42: 1
C43: dr nila | H43: 1 | Q43: dr rezky | U43: 1 | V43: 1 | AE43: dr. Michael | AS43: dr margareta | AV43: 1 | AX43: 1 | BF43: 11,9,26 | BG43: dr arif budiman | BI43: 1 | BL43: 1 | BM43: 1 | BU43: dr arif | BW43: 1 | BY43: 1 | BZ43: 1
C44: dr saka | E44: 1 | H44: 1 | Q44: dr wicaksono | U44: 1 | V44: 1 | AE44: dr. wisuda | AS44: dr melfa | AW44: 1 | AX44: 1 | BF44: yurlis | BG44: dr saka | BK44: 1 | BL44: 1 | BU44: dr rungan malam | BY44: 3 | BZ44: 1
...

Sheet skrining
G2: Harga yang di ajukan oleh marketing | I2: Toko Roti majestik
C3: Tanggal | D3: skrining internal | E3: skrining external | G3: Roti @ 3500 | H3: 3500 | I3: Tanggal | J3: jml | K3: Harga | L3: Total | M3: jml | N3: Harga | O3: Total | P3: jml | Q3: Harga | R3: Total | S3: jml | T3: Harga | U3: Total | V3: total seluruh
C4: 1,9,26 | D4: 40 | G4: dus @700 (per 1 box 70000) | H4: 700 | I4: 1,9,26 | J4: 40 | K4: 6000 | L4: =J4*K4 -> 240000 | O4: =M4*N4 -> 0 | R4: =P4*Q4 -> 0 | U4: =S4*T4 -> 0 | V4: =L4+O4+R4 -> 240000
C5: 8,9,26 | D5: 60 | G5: gelas cleo 220ml @ 458 (harga perdus 22000) | H5: 458 | I5: 8,9,26 | J5: 60 | K5: 6000 | L5: =J5*K5 -> 360000 | O5: =M5*N5 -> 0 | R5: =P5*Q5 -> 0 | U5: =S5*T5 -> 0 | V5: =L5+O5+R5 -> 360000
C6: 9,9,26 | E6: 40 | G6: total | H6: =SUM(H3:H5) -> 4658 | I6: 9,9,26 | J6: 40 | K6: 6000 | L6: =J6*K6 -> 240000 | O6: =M6*N6 -> 0 | R6: =P6*Q6 -> 0 | U6: =S6*T6 -> 0 | V6: =L6+O6+R6 -> 240000
C7: 10,9,26 | D7: 10 | E7: 42 | I7: 10,9,26 | J7: 52 | K7: 6000 | L7: =J7*K7 -> 312000 | O7: =M7*N7 -> 0 | R7: =P7*Q7 -> 0 | U7: =S7*T7 -> 0 | V7: =L7+O7+R7 -> 312000
C8: 15,9,26 | D8: 25 | E8: 40 | I8: 15,9,26 | J8: 65 | K8: 6000 | L8: =J8*K8 -> 390000 | O8: =M8*N8 -> 0 | R8: =P8*Q8 -> 0 | U8: =S8*T8 -> 0 | V8: =L8+O8+R8 -> 390000
C9: 16,9,26 | E9: 40 | I9: 16,9,26 | J9: 40 | K9: 6000 | L9: =J9*K9 -> 240000 | O9: =M9*N9 -> 0 | R9: =P9*Q9 -> 0 | U9: =S9*T9 -> 0 | V9: =L9+O9+R9 -> 240000
C10: 17,9,26 | D10: 8 | I10: 17,9,26 | J10: 8 | K10: 6000 | L10: =J10*K10 -> 48000 | O10: =M10*N10 -> 0 | R10: =P10*Q10 -> 0 | U10: =S10*T10 -> 0 | V10: =L10+O10+R10 -> 48000
C11: 22,09,2026 | D11: 25 | I11: 22,9,26 | J11: 25 | K11: 6000 | L11: =J11*K11 -> 150000 | O11: =M11*N11 -> 0 | R11: =P11*Q11 -> 0 | U11: =S11*T11 -> 0 | V11: =L11+O11+R11 -> 150000
C12: 24,9,26 | D12: 10 | I12: 24,9,26 | J12: 10 | K12: 6000 | L12: =J12*K12 -> 60000 | O12: =M12*N12 -> 0 | R12: =P12*Q12 -> 0 | U12: =S12*T12 -> 0 | V12: =L12+O12+R12 -> 60000
C13: 29,9,26 | D13: 27 | I13: 29,9,26 | J13: 27 | K13: 6000 | L13: =J13*K13 -> 162000 | O13: =M13*N13 -> 0 | R13: =P13*Q13 -> 0 | U13: =S13*T13 -> 0 | V13: =L13+O13+R13 -> 162000
L14: =J14*K14 -> 0 | O14: =M14*N14 -> 0 | R14: =P14*Q14 -> 0 | U14: =S14*T14 -> 0 | V14: =L14+O14+R14 -> 0
L15: =J15*K15 -> 0 | O15: =M15*N15 -> 0 | R15: =P15*Q15 -> 0 | U15: =S15*T15 -> 0 | V15: =L15+O15+R15 -> 0
L16: =J16*K16 -> 0 | O16: =M16*N16 -> 0 | R16: =P16*Q16 -> 0 | U16: =S16*T16 -> 0 | V16: =L16+O16+R16 -> 0
L17: =J17*K17 -> 0 | O17: =M17*N17 -> 0 | R17: =P17*Q17 -> 0 | U17: =S17*T17 -> 0 | V17: =L17+O17+R17 -> 0
L18: =J18*K18 -> 0 | O18: =M18*N18 -> 0 | R18: =P18*Q18 -> 0 | U18: =S18*T18 -> 0 | V18: =L18+O18+R18 -> 0
L19: =J19*K19 -> 0 | O19: =M19*N19 -> 0 | R19: =P19*Q19 -> 0 | U19: =S19*T19 -> 0 | V19: =L19+O19+R19 -> 0
L20: =J20*K20 -> 0 | O20: =M20*N20 -> 0 | R20: =P20*Q20 -> 0 | U20: =S20*T20 -> 0 | V20: =L20+O20+R20 -> 0
L21: =J21*K21 -> 0 | O21: =M21*N21 -> 0 | R21: =P21*Q21 -> 0 | U21: =S21*T21 -> 0 | V21: =L21+O21+R21 -> 0
L22: =J22*K22 -> 0 | O22: =M22*N22 -> 0 | R22: =P22*Q22 -> 0 | U22: =S22*T22 -> 0 | V22: =L22+O22+R22 -> 0
L23: =J23*K23 -> 0 | O23: =M23*N23 -> 0 | R23: =P23*Q23 -> 0 | U23: =S23*T23 -> 0 | V23: =L23+O23+R23 -> 0
C24: TOTAL | D24: =SUM(D4:D23) -> 205 | E24: =SUM(E4:E23) -> 162 | L24: =J24*K24 -> 0 | O24: =M24*N24 -> 0 | R24: =P24*Q24 -> 0 | U24: =S24*T24 -> 0 | V24: =L24+O24+R24 -> 0
C25: Total Semua | E25: =D24+E24 -> 367 | L25: =J25*K25 -> 0 | O25: =M25*N25 -> 0 | R25: =P25*Q25 -> 0 | U25: =S25*T25 -> 0 | V25: =L25+O25+R25 -> 0
L26: =J26*K26 -> 0 | O26: =M26*N26 -> 0 | R26: =P26*Q26 -> 0 | U26: =S26*T26 -> 0 | V26: =L26+O26+R26 -> 0
C27: budjet skrining seharusnya | E27: =E25*4658 -> 1709486 | L27: =J27*K27 -> 0 | O27: =M27*N27 -> 0 | R27: =P27*Q27 -> 0 | U27: =S27*T27 -> 0 | V27: =L27+O27+R27 -> 0
C28: budgjet skrining kenyataannya | E28: =V39 -> 2626986 | L28: =J28*K28 -> 0 | O28: =M28*N28 -> 0 | R28: =P28*Q28 -> 0 | U28: =S28*T28 -> 0 | V28: =L28+O28+R28 -> 0
C29: selisih | E29: =E27-E28 -> -917500 | L29: =J29*K29 -> 0 | O29: =M29*N29 -> 0 | R29: =P29*Q29 -> 0 | U29: =S29*T29 -> 0 | V29: =L29+O29+R29 -> 0
L30: =J30*K30 -> 0 | O30: =M30*N30 -> 0 | R30: =P30*Q30 -> 0 | U30: =S30*T30 -> 0 | V30: =L30+O30+R30 -> 0
L31: =J31*K31 -> 0 | O31: =M31*N31 -> 0 | R31: =P31*Q31 -> 0 | U31: =S31*T31 -> 0 | V31: =L31+O31+R31 -> 0
L32: =J32*K32 -> 0 | O32: =M32*N32 -> 0 | R32: =P32*Q32 -> 0 | U32: =S32*T32 -> 0 | V32: =L32+O32+R32 -> 0
L33: =J33*K33 -> 0 | O33: =M33*N33 -> 0 | R33: =P33*Q33 -> 0 | U33: =S33*T33 -> 0 | V33: =L33+O33+R33 -> 0
L34: =J34*K34 -> 0 | O34: =M34*N34 -> 0 | R34: =P34*Q34 -> 0 | U34: =S34*T34 -> 0 | V34: =L34+O34+R34 -> 0
I35: total | J35: =SUM(J4:J34) -> 367 | L35: =SUM(L4:L34) -> 2202000 | M35: =SUM(M4:M34) -> 0 | O35: =SUM(O4:O34) -> 0 | P35: =SUM(P4:P34) -> 0 | R35: =SUM(R4:R34) -> 0 | S35: =SUM(S4:S34) -> 0 | U35: =SUM(U4:U34) -> 0 | V35: =SUM(V4:V34) -> 2202000
V36: =L35+O35+R35 -> 2202000
V37: =J35+M35 -> 367 | W37: total jmlh roti
S38: =H4+H5 -> 1158 | T38: total dus dan air | V38: =S38*V37 -> 424986
V39: =V36+V38 -> 2626986 | W39: total roti dan dus air

Sheet snack stuba
H2: Harga
B3: Tanggal | C3: snack box | D3: makan | E3: le mineral 330ml | F3: le mineral 600ml | G3: asal stuba | H3: snack @ 12000 | I3: 12000
E4: 40 | H4: dus @700 (per 1 box 70000) | I4: 700
H6: le mineral 330ml @ 1541 (harga per dus 37000) | I6: 1541
H7: total | I7: =SUM(I3:I6) -> 14241
H9: Harga Standar @ 50.000
H10: makan @ 30,000 | I10: 30000
H11: le mineral 330ml @ 1541 (harga per dus 37000) | I11: 1541
H12: snack @ 12000 | I12: =SUM(I10:I11) -> 31541
B25: Total | C25: =SUM(C4:C24) -> 0 | E25: =SUM(E4:E24) -> 40 | F25: =SUM(F4:F24) -> 0
C26: 12000 | E26: 1541 | F26: 1958
B27: total | C27: =C25*C26 -> 0 | E27: =E25*E26 -> 61640 | F27: =F25*F26 -> 0
B28: total semua | C28: =C27+E27+F27 -> 61640

Sheet makan stuba
K2: Harga Standar @ 50.000
B3: Tanggal | C3: Asal Stuba | D3: Jumlh makan | F3: le minera 330 | G3: le mineral 600 | H3: nama rumah makan | I3: harga per box | J3: total biaya makan | K3: makan @ 30,000 | L3: 30000
K4: le mineral 330ml @ 1541 (harga per dus 37000) | L4: 1541
K5: total | L5: =SUM(L3:L4) -> 31541

Sheet PT
G2: Harga Standar @ 50.000
B3: Tanggal | C3: snack annisa | D3: le mineral 330 | E3: le mineral 600 | F3: jumlh buah | G3: makan @ 30,000 | H3: 30000
B4: 07,09,26 | D4: 15 | G4: le mineral 330ml @ 1541 (harga per dus 37000) | H4: 1541
B5: 16.9.26 | D5: 48 | F5: 6 | G5: total | H5: =SUM(H3:H4) -> 31541
B6: 21,09,2026 | D6: 35
B7: 24,09,26 | D7: 24
B19: total | C19: =SUM(C4:C18) -> 0 | D19: =SUM(D4:D18) -> 122 | E19: =SUM(E4:E18) -> 0 | F19: =SUM(F4:F18) -> 6
C20: 12000 | D20: 1541 | E20: 1958 | F20: 5833
B21: total | C21: =C20*C19 -> 0 | D21: =D20*D19 -> 188002 | E21: =E20*E19 -> 0 | F21: =F20*F19 -> 34998

Sheet ok snack
I2: setiap item dikeluarkan 5
B3: tanggal / jam | C3: jumlah pasien | D3: pagi 09,00 | E3: sore 15,00 | F3: kopi 3in 1 | G3: kopi ka | I3: tanggal / jam | J3: yang diinput adalah yang di makan
J4: pop mie | K4: kopi 3in 1 | L4: roti
B5: 46266 | C5: 5 | D5: 5 | I5: 46266 | J5: 5 | K5: 5 | L5: 5
C6: 5 | E6: 5 | F6: 2 | G6: 2 | I6: 02,09,2026 | J6: 5 | K6: 5 | L6: 5
B7: 02,9,2026 | C7: 3 | D7: 4 | I7: 3.9.26 | J7: 5 | K7: 5 | L7: 5
C8: 2 | E8: 3 | I8: 05.09.2026 | J8: 5 | K8: 3 | L8: 5
B9: 3.9.26 | C9: 2 | D9: 6 | I9: 6,9,26 | J9: 5 | K9: 5 | L9: 5
C10: 3 | E10: 3 | F10: 3 | G10: 2 | I10: 7.09.26 | J10: 5 | K10: 5 | L10: 5
B11: 04.09.2026 | C11: 5 | D11: 4 | I11: 8.9.26 | J11: 5 | K11: 5 | L11: 5
C12: 4 | E12: 3 | F12: 3 | G12: 2 | I12: 9,9,2026 | J12: 5 | K12: 5 | L12: 5
B13: 05.09.2026 | C13: 8 | D13: 5 | I13: 10,9,2026 | J13: 5 | K13: 5 | L13: 5
C14: 7 | E14: 5 | F14: 3 | G14: 2 | I14: 11.9.26 | J14: 2 | K14: 2 | L14: 3
B15: 6,9,26 | C15: 5 | D15: 6 | I15: 12.09.26 | J15: 5 | K15: 3 | L15: 5
B16: 7,9,26 | C16: 3 | D16: 2 | I16: 13.09.26 | J16: 5 | K16: 5 | L16: 5
C17: 6 | E17: 3 | F17: 3 | G17: 2 | I17: 14,9,26 | J17: 0 | K17: 0 | L17: 3
I18: 15,9,26 | J18: 5 | K18: 5 | L18: 5
B19: 8.9.26 | C19: 3 | D19: 5 | E19: 4 | I19: 16,09,2026 | J19: 5 | K19: 5 | L19: 5
I20: 17,09,2026 | J20: 0 | K20: 0 | L20: 5
B21: 9.9.26 | C21: 2 | D21: 4 | I21: 18.9.26 | J21: 5 | K21: 5 | L21: 5
C22: 3 | E22: 3 | F22: 3 | G22: 2 | I22: 19,9,26 | J22: 5 | K22: 5 | L22: 5
B23: 10.9.26 | C23: 5 | D23: 5 | I23: 20,09,2026 | J23: 5 | K23: 5 | L23: 5
C24: 2 | E24: 6 | F24: 3 | G24: 2 | I24: 21,9,26
B25: 11.9.26 | C25: 3 | D25: 3 | I25: 22,9,26
C26: 3 | E26: 5 | F26: 3 | G26: 2 | I26: 23,9,26 | J26: 5 | K26: 5 | L26: 5
B27: 12.09.26 | C27: 8 | D27: 5 | I27: 24,09,26 | J27: 5 | K27: 5 | L27: 5
C28: 7 | E28: 5 | F28: 3 | G28: 3 | I28: 25,9,26 | J28: 5 | K28: 5 | L28: 5
B29: 13.09.26 | C29: 3 | D29: 3 | I29: 26,9,26
B30: 14,9,26 | C30: 3 | D30: 3 | E30: 2 | F30: 5 | G30: 3 | I30: 27,9,26 | J30: 5 | K30: 5 | L30: 5
C31: 8 | I31: 28,09,2026 | J31: 5 | K31: 5 | L31: 5
B32: 15,9,26 | C32: 3 | D32: 4
C33: 4 | E33: 6 | F33: 3 | G33: 2
B34: 16,09,2026 | C34: 2 | D34: 2
C35: 3 | E35: 5 | F35: 3 | G35: 2
B37: 17,9,26 | C37: 4 | D37: 6 | I37: total | J37: =SUM(J5:J36) -> 107 | K37: =SUM(K5:K36) -> 103 | L37: =SUM(L5:L36) -> 116
C38: 4 | E38: 6 | F38: 3 | G38: 2 | J38: 4424 | K38: 1310 | L38: 7500
B39: 18.9.26 | C39: 2 | D39: 5 | J39: =J37*J38 -> 473368 | K39: =K37*K38 -> 134930 | L39: =L37*L38 -> 870000
C40: 4 | E40: 5 | F40: 3 | G40: 2
B41: 19,9,26 | C41: 1 | D41: 2 | I41: ok malam | J41: =J39+K39+L39 -> 1478298
C42: 4 | E42: 4 | F42: 3 | G42: 2
...

Sheet ok mkn
B3: tanggal / jam | C3: jumlah pasien | D3: makan | J3: makan | P3: makan | V3: gula (kg) | W3: petugas
D4: pagi | E4: tempe goreng | F4: kopi 3in 1 | G4: kopi ka | H4: gula DM | I4: the | J4: siang | K4: tempe goreng | L4: kopi 3in 1 | M4: kopi ka | N4: gula DM | O4: the | P4: sore | Q4: tempe goreng | R4: kopi 3in 1 | S4: kopi ka | T4: gula DM | U4: the
B5: 46266 | C5: 8 | D5: 7 | F5: 3 | G5: 2 | H5: 5 | I5: 4
C6: 8 | J6: 7 | K6: 1
C7: 2 | P7: 3 | W7: bekti, fahrul, bayu, ismi
B8: 2,9,2026 | C8: 3 | D8: 5 | F8: 3 | G8: 2 | H8: 5 | I8: 4
C9: 8 | J9: 8 | K9: 1 | O9: 1
C10: 3 | P10: 3
C11: 4
B12: 3.9.26 | C12: 8 | D12: 6 | F12: 3 | G12: 2 | H12: 5 | I12: 4 | P12: 3
C13: 7 | J13: 5 | K13: 1 | O13: 1
C14: 14 ktrk | P14: 8
B18: 04.09.2026 | C18: 5 | D18: 4 | F18: 3 | G18: 2 | H18: 5 | J18: 6
C19: 4
C20: 2
B21: 05.09.2026 | C21: 8 | D21: 3 | F21: 3 | G21: 2 | H21: 5 | I21: 4
C22: 15 | J22: 9
C23: 4 | P23: 3
B24: 6,9,26 | C24: 9 | D24: 7
C25: 8 | F25: 3 | G25: 3 | H25: 4 | I25: 4 | J25: 6
B26: 7,9,26 | C26: 4 | D26: 3 | G26: 2 | H26: 5 | I26: 4 | W26: bekti yurlis titik ridwan
D27: 11 | J27: 8 | K27: 1
D28: 5 | P28: 3
B30: 8.9.26 | C30: 3 | D30: 4 | F30: 3 | G30: 2 | H30: 3 | I30: 4
C31: 7
B33: 9.9.26 | C33: 3 | D33: 4 | F33: 3 | G33: 2 | H33: 5 | I33: 4
C34: 10 | J34: 9 | K34: 1 | O34: 1
C35: 4 | P35: 3
B36: 10,9,2026 | C36: 2 | D36: 2 | F36: 3 | G36: 2 | H36: 5 | I36: 4
C37: 7 | J37: 7
C38: 13 | P38: 7
B39: 11.9.26 | C39: 4 | D39: 4 | F39: 3 | G39: 2 | H39: 5 | I39: 4
C40: 10 | J40: 8 | K40: 1 | O40: 1
C41: 1 | P41: 5
C42: 4 | P42: 6
B43: 12.09.26 | C43: 8 | D43: 5 | F43: 3 | G43: 3 | H43: 4 | I43: 4
C44: 15 | J44: 9 | K44: 1 | P44: 5
B45: 13.09.26 | C45: 3 | D45: 3 | F45: 3 | G45: 3 | H45: 4 | I45: 4
B46: 14,9,26 | C46: 3 | D46: 5 | F46: 3 | G46: 4 | H46: 5 | I46: 5 | J46: 6 | K46: 1
C47: 6 | O47: 1 | P47: 3
...

Sheet supplier
B2: Kebutuhan Pasien (Supl Pak Urip)
B4: Nama B.M | C4: Satuan | E4: Tanggal | CU4: total harga
D5: harga | E5: 1 | H5: 2 | K5: 3 | N5: 4 | Q5: 5 | T5: 6 | W5: 7 | Z5: 8 | AC5: 9 | AF5: 10 | AI5: 11 | AL5: 12 | AO5: 13 | AR5: 14 | AU5: 15 | AX5: 16 | BA5: 17 | BD5: 18 | BG5: 19 | BJ5: 20 | BM5: 21 | BP5: 22 | BS5: 23 | BV5: 24 | BY5: 25 | CB5: 26 | CE5: 27 | CH5: 28 | CK5: 29 | CN5: 30 | CQ5: 31
D6: awal | E6: datang | F6: harga | G6: total | H6: datang | I6: harga | J6: total | K6: datang | L6: harga | M6: total | N6: datang | O6: harga | P6: total | Q6: datang | R6: harga | S6: total | T6: datang | U6: harga | V6: total | W6: datang | X6: harga | Y6: total | Z6: datang | AA6: harga | AB6: total | AC6: datang | AD6: harga | AE6: total | AF6: datang | AG6: harga | AH6: total | AI6: datang | AJ6: harga | AK6: total | AL6: datang | AM6: harga | AN6: total | AO6: datang | AP6: harga | AQ6: total | AR6: datang | AS6: harga | AT6: total | AU6: datang | AV6: harga | AW6: total | AX6: datang | AY6: harga | AZ6: total | BA6: datang | BB6: harga | BC6: total | BD6: datang | BE6: harga | BF6: total | BG6: datang | BH6: harga | BI6: total | BJ6: datang | BK6: harga | BL6: total | BM6: datang | BN6: harga | BO6: total | BP6: datang | BQ6: harga | BR6: total | BS6: datang | BT6: harga | BU6: total | BV6: datang | BW6: harga | BX6: total | BY6: datang | BZ6: harga | CA6: total | CB6: datang | CC6: harga | CD6: total | CE6: datang | CF6: harga | CG6: total | CH6: datang | CI6: harga | CJ6: total | CK6: datang | CL6: harga | CM6: total | CN6: datang | CO6: harga | CP6: total | CQ6: datang | CR6: harga | CS6: total | CT6: total
B7: Gol Ayam | D7: awal
B8: Ati Ayam | C8: pcs | E8: 60 | F8: 2800 | G8: =E8*F8 -> 168000 | J8: =H8*I8 -> 0 | K8: 50 | L8: 2800 | M8: =K8*L8 -> 140000 | P8: =N8*O8 -> 0 | S8: =Q8*R8 -> 0 | T8: 60 | U8: 2800 | V8: =T8*U8 -> 168000 | W8: 60 | X8: 2800 | Y8: =W8*X8 -> 168000 | AB8: =Z8*AA8 -> 0 | AC8: 40 | AD8: 2800 | AE8: =AC8*AD8 -> 112000 | AH8: =AF8*AG8 -> 0 | AI8: 60 | AJ8: 2800 | AK8: =AI8*AJ8 -> 168000 | AN8: =AL8*AM8 -> 0 | AO8: 50 | AP8: 2800 | AQ8: =AO8*AP8 -> 140000 | AT8: =AR8*AS8 -> 0 | AU8: 70 | AV8: 2800 | AW8: =AU8*AV8 -> 196000 | AX8: 60 | AY8: 2800 | AZ8: =AX8*AY8 -> 168000 | BA8: 60 | BB8: 2800 | BC8: =BA8*BB8 -> 168000 | BF8: =BD8*BE8 -> 0 | BG8: 60 | BH8: 2800 | BI8: =BG8*BH8 -> 168000 | BL8: =BJ8*BK8 -> 0 | BM8: 60 | BN8: 2800 | BO8: =BM8*BN8 -> 168000 | BR8: =BP8*BQ8 -> 0 | BS8: 60 | BT8: 2800 | BU8: =BS8*BT8 -> 168000 | BX8: =BV8*BW8 -> 0 | BY8: 80 | BZ8: 2800 | CA8: =BY8*BZ8 -> 224000 | CD8: =CB8*CC8 -> 0 | CE8: 35 | CF8: 2800 | CG8: =CE8*CF8 -> 98000 | CJ8: =CH8*CI8 -> 0 | CK8: 50 | CL8: 2800 | CM8: =CK8*CL8 -> 140000 | CP8: =CN8*CO8 -> 0 | CS8: =CQ8*CR8 -> 0 | CT8: =E8+H8+K8+N8+Q8+T8+W8+Z8+AC8+AF8+AI8+AL8+AO8+AR8+AU8+AX8+BA8+BD8+BG8+BJ8+BM8+BP8+BS8+BV8+BY8+CB8+CE8+CH8+CK8+CN8+CQ8 -> 915 | CU8: =G8+J8+M8+P8+S8+V8+Y8+AB8+AE8+AH8+AK8+AN8+AQ8+AT8+AW8+AZ8+BC8+BF8+BI8+BL8+BO8+BR11+BU8+BX8+CA8+CD8+CG8+CJ8+CM8+CP8+CS8 -> 2562000
B9: Ayam Negeri @8 | C9: ekor | G9: =E9*F9 -> 0 | H9: 2 | I9: 38000 | J9: =H9*I9 -> 76000 | M9: =K9*L9 -> 0 | N9: 2 | O9: 38000 | P9: =N9*O9 -> 76000 | S9: =Q9*R9 -> 0 | V9: =T9*U9 -> 0 | W9: 1.5 | X9: 60000 | Y9: =W9*X9 -> 90000 | AB9: =Z9*AA9 -> 0 | AC9: 2 | AD9: 38000 | AE9: =AC9*AD9 -> 76000 | AH9: =AF9*AG9 -> 0 | AK9: =AI9*AJ9 -> 0 | AN9: =AL9*AM9 -> 0 | AQ9: =AO9*AP9 -> 0 | AT9: =AR9*AS9 -> 0 | AU9: 7 | AV9: 38000 | AW9: =AU9*AV9 -> 266000 | AX9: 2 | AY9: 70000 | AZ9: =AX9*AY9 -> 140000 | BC9: =BA9*BB9 -> 0 | BF9: =BD9*BE9 -> 0 | BI9: =BG9*BH9 -> 0 | BL9: =BJ9*BK9 -> 0 | BO9: =BM9*BN9 -> 0 | BR9: =BP9*BQ9 -> 0 | BU9: =BS9*BT9 -> 0 | BX9: =BV9*BW9 -> 0 | BY9: 8 | BZ9: 38000 | CA9: =BY9*BZ9 -> 304000 | CB9: 18 | CC9: 38000 | CD9: =CB9*CC9 -> 684000 | CG9: =CE9*CF9 -> 0 | CH9: 8 | CI9: 38000 | CJ9: =CH9*CI9 -> 304000 | CM9: =CK9*CL9 -> 0 | CP9: =CN9*CO9 -> 0 | CS9: =CQ9*CR9 -> 0 | CT9: =E9+H9+K9+N9+Q9+T9+W9+Z9+AC9+AF9+AI9+AL9+AO9+AR9+AU9+AX9+BA9+BD9+BG9+BJ9+BM9+BP9+BS9+BV9+BY9+CB9+CE9+CH9+CK9+CN9+CQ9 -> 50.5 | CU9: =G9+J9+M9+P9+S9+V9+Y9+AB9+AE9+AH9+AK9+AN9+AQ9+AT9+AW9+AZ9+BC9+BF9+BI9+BL9+BO9+BR9+BU9+BX9+CA9+CD9+CG9+CJ9+CM9+CP9+CS9 -> 2016000
B10: Fillet Ayam | C10: kg | D10: 48000 | E10: 2 | F10: 58000 | G10: =E10*F10 -> 116000 | H10: 1 | I10: 58000 | J10: =H10*I10 -> 58000 | K10: 4 | L10: 58000 | M10: =K10*L10 -> 232000 | N10: 3 | O10: 58000 | P10: =N10*O10 -> 174000 | S10: =Q10*R10 -> 0 | V10: =T10*U10 -> 0 | Y10: =W10*X10 -> 0 | AB10: =Z10*AA10 -> 0 | AC10: 1 | AD10: 58000 | AE10: =AC10*AD10 -> 58000 | AF10: 3 | AG10: 60000 | AH10: =AF10*AG10 -> 180000 | AI10: 6 | AJ10: 58000 | AK10: =AI10*AJ10 -> 348000 | AN10: =AL10*AM10 -> 0 | AO10: 3 | AP10: 58000 | AQ10: =AO10*AP10 -> 174000 | AT10: =AR10*AS10 -> 0 | AW10: =AU10*AV10 -> 0 | AZ10: =AX10*AY10 -> 0 | BC10: =BA10*BB10 -> 0 | BD10: 2 | BE10: 60000 | BF10: =BD10*BE10 -> 120000 | BI10: =BG10*BH10 -> 0 | BJ10: 2 | BK10: 58000 | BL10: =BJ10*BK10 -> 116000 | BO10: =BM10*BN10 -> 0 | BR10: =BP10*BQ10 -> 0 | BS10: 5 | BT10: 58000 | BU10: =BS10*BT10 -> 290000 | BX10: =BV10*BW10 -> 0 | CA10: =BY10*BZ10 -> 0 | CB10: 3 | CC10: 58000 | CD10: =CB10*CC10 -> 174000 | CG10: =CE10*CF10 -> 0 | CH10: 4 | CI10: 58000 | CJ10: =CH10*CI10 -> 232000 | CM10: =CK10*CL10 -> 0 | CP10: =CN10*CO10 -> 0 | CS10: =CQ10*CR10 -> 0 | CT10: =E10+H10+K10+N10+Q10+T10+W10+Z10+AC10+AF10+AI10+AL10+AO10+AR10+AU10+AX10+BA10+BD10+BG10+BJ10+BM10+BP10+BS10+BV10+BY10+CB10+CE10+CH10+CK10+CN10+CQ10 -> 39 | CU10: =G10+J10+M10+P10+S10+V10+Y10+AB10+AE10+AH10+AK10+AN10+AQ10+AT10+AW10+AZ10+BC10+BF10+BI10+BL10+BO10+BR10+BU10+BX10+CA10+CD10+CG10+CJ10+CM10+CP10+CS10 -> 2272000
B11: fillet Ayam Giling | C11: kg | D11: 50000 | E11: 4 | F11: 58000 | G11: =E11*F11 -> 232000 | J11: =H11*I11 -> 0 | K11: 4 | L11: 58000 | M11: =K11*L11 -> 232000 | P11: =N11*O11 -> 0 | S11: =Q11*R11 -> 0 | V11: =T11*U11 -> 0 | Y11: =W11*X11 -> 0 | Z11: 2 | AA11: 58000 | AB11: =Z11*AA11 -> 116000 | AE11: =AC11*AD11 -> 0 | AH11: =AF11*AG11 -> 0 | AK11: =AI11*AJ11 -> 0 | AN11: =AL11*AM11 -> 0 | AO11: 2 | AP11: 60000 | AQ11: =AO11*AP11 -> 120000 | AT11: =AR11*AS11 -> 0 | AU11: 1 | AV11: 58000 | AW11: =AU11*AV11 -> 58000 | AX11: 7 | AY11: 58000 | AZ11: =AX11*AY11 -> 406000 | BC11: =BA11*BB11 -> 0 | BF11: =BD11*BE11 -> 0 | BI11: =BG11*BH11 -> 0 | BL11: =BJ11*BK11 -> 0 | BO11: =BM11*BN11 -> 0 | BR11: =BP11*BQ11 -> 0 | BS11: 4 | BT11: 58000 | BU11: =BS11*BT11 -> 232000 | BX11: =BV11*BW11 -> 0 | BY11: 9 | BZ11: 58000 | CA11: =BY11*BZ11 -> 522000 | CB11: 4 | CC11: 58000 | CD11: =CB11*CC11 -> 232000 | CG11: =CE11*CF11 -> 0 | CH11: 4 | CI11: 58000 | CJ11: =CH11*CI11 -> 232000 | CM11: =CK11*CL11 -> 0 | CP11: =CN11*CO11 -> 0 | CS11: =CQ11*CR11 -> 0 | CT11: =E11+H11+K11+N11+Q11+T11+W11+Z11+AC11+AF11+AI11+AL11+AO11+AR11+AU11+AX11+BA11+BD11+BG11+BJ11+BM11+BP11+BS11+BV11+BY11+CB11+CE11+CH11+CK11+CN11+CQ11 -> 41 | CU11: =G11+J11+M11+P11+S11+V11+Y11+AB11+AE11+AH11+AK11+AN11+AQ11+AT11+AW11+AZ11+BC11+BF11+BI11+BL11+BO11+BR11+BU11+BX11+CA11+CD11+CG11+CJ11+CM11+CP11+CS11 -> 2382000
B12: Gol Daging | AE12: =AC12*AD12 -> 0
B13: Bakso sapi @50 | C13: bh | D13: 45000 | G13: =E13*F13 -> 0 | J13: =H13*I13 -> 0 | M13: =K13*L13 -> 0 | N13: 4 | O13: 35000 | P13: =N13*O13 -> 140000 | S13: =Q13*R13 -> 0 | V13: =T13*U13 -> 0 | Y13: =W13*X13 -> 0 | AB13: =Z13*AA13 -> 0 | AC13: 3 | AD13: 35000 | AE13: =AC13*AD13 -> 105000 | AH13: =AF13*AG13 -> 0 | AI13: 3 | AJ13: 30000 | AK13: =AI13*AJ13 -> 90000 | AN13: =AL13*AM13 -> 0 | AO13: 3 | AP13: 35000 | AQ13: =AO13*AP13 -> 105000 | AT13: =AR13*AS13 -> 0 | AW13: =AU13*AV13 -> 0 | AZ13: =AX13*AY13 -> 0 | BC13: =BA13*BB13 -> 0 | BF13: =BD13*BE13 -> 0 | BI13: =BG13*BH13 -> 0 | BL13: =BJ13*BK13 -> 0 | BO13: =BM13*BN13 -> 0 | BR13: =BP13*BQ13 -> 0 | BU13: =BS13*BT13 -> 0 | BX13: =BV13*BW13 -> 0 | CA13: =BY13*BZ13 -> 0 | CD13: =CB13*CC13 -> 0 | CG13: =CE13*CF13 -> 0 | CJ13: =CH13*CI13 -> 0 | CK13: 3 | CL13: 35000 | CM13: =CK13*CL13 -> 105000 | CP13: =CN13*CO13 -> 0 | CS13: =CQ13*CR13 -> 0 | CT13: =E13+H13+K13+N13+Q13+T13+W13+Z13+AC13+AF13+AI13+AL13+AO13+AR13+AU13+AX13+BA13+BD13+BG13+BJ13+BM13+BP13+BS13+BV13+BY13+CB13+CE13+CH13+CK13+CN13+CQ13 -> 16 | CU13: =G13+J13+M13+P13+S13+V13+Y13+AB13+AE13+AH13+AK13+AN13+AQ13+AT13+AW13+AZ13+BC13+BF13+BI13+BL13+BO13+BR13+BU13+BX13+CA13+CD13+CG13+CJ13+CM13+CP13+CS13 -> 545000
B14: Bakso Ikan | AC14: 3 | AD14: 32000 | AE14: =AC14*AD14 -> 96000 | AR14: 3 | AS14: 35000 | AT14: =AR14*AS14 -> 105000 | BI14: =BG14*BH14 -> 0
B15: Daging Gandik | C15: kg | D15: 135000 | G15: =E15*F15 -> 0 | H15: 6 | I15: 150000 | J15: =H15*I15 -> 900000 | M15: =K15*L15 -> 0 | P15: =N15*O15 -> 0 | S15: =Q15*R15 -> 0 | V15: =T15*U15 -> 0 | Y15: =W15*X15 -> 0 | AB15: =Z15*AA15 -> 0 | AE15: =AC15*AD15 -> 0 | AH15: =AF15*AG15 -> 0 | AK15: =AI15*AJ15 -> 0 | AN15: =AL15*AM15 -> 0 | AO15: 2.5 | AP15: 150000 | AQ15: =AO15*AP15 -> 375000 | AR15: 10.5 | AS15: 150000 | AT15: =AR15*AS15 -> 1575000 | AW15: =AU15*AV15 -> 0 | AZ15: =AX15*AY15 -> 0 | BC15: =BA15*BB15 -> 0 | BD15: 8 | BE15: 150000 | BF15: =BD15*BE15 -> 1200000 | BI15: =BG15*BH15 -> 0 | BJ15: 10 | BK15: 150000 | BL15: =BJ15*BK15 -> 1500000 | BO15: =BM15*BN15 -> 0 | BR15: =BP15*BQ15 -> 0 | BU15: =BS15*BT15 -> 0 | BX15: =BV15*BW15 -> 0 | CA15: =BY15*BZ15 -> 0 | CD15: =CB15*CC15 -> 0 | CG15: =CE15*CF15 -> 0 | CJ15: =CH15*CI15 -> 0 | CM15: =CK15*CL15 -> 0 | CP15: =CN15*CO15 -> 0 | CS15: =CQ15*CR15 -> 0 | CT15: =E15+H15+K15+N15+Q15+T15+W15+Z15+AC15+AF15+AI15+AL15+AO15+AR15+AU15+AX15+BA15+BD15+BG15+BJ15+BM15+BP15+BS15+BV15+BY15+CB15+CE15+CH15+CK15+CN15+CQ15 -> 37 | CU15: =G15+J15+M15+P15+S15+V15+Y15+AB15+AE15+AH15+AK15+AN15+AQ15+AT15+AW15+AZ15+BC15+BF15+BI15+BL15+BO15+BR15+BU15+BX15+CA15+CD15+CG15+CJ15+CM15+CP15+CS15 -> 5550000
B16: Gandik Giling | C16: kg | D16: 135000 | G16: =E16*F16 -> 0 | J16: =H16*I16 -> 0 | M16: =K16*L16 -> 0 | N16: 1 | O16: 150000 | P16: =N16*O16 -> 150000 | S16: =Q16*R16 -> 0 | V16: =T16*U16 -> 0 | Y16: =W16*X16 -> 0 | AB16: =Z16*AA16 -> 0 | AC16: 2 | AD16: 150000 | AE16: =AC16*AD16 -> 300000 | AF16: 2 | AG16: 150000 | AH16: =AF16*AG16 -> 300000 | AK16: =AI16*AJ16 -> 0 | AL16: 4 | AM16: 150000 | AN16: =AL16*AM16 -> 600000 | AQ16: =AO16*AP16 -> 0 | AR16: 1 | AS16: 150000 | AT16: =AR16*AS16 -> 150000 | AU16: 1.5 | AV16: 150000 | AW16: =AU16*AV16 -> 225000 | AZ16: =AX16*AY16 -> 0 | BC16: =BA16*BB16 -> 0 | BF16: =BD16*BE16 -> 0 | BG16: 3 | BH16: 150000 | BI16: =BG16*BH16 -> 450000 | BJ16: 1 | BK16: 150000 | BL16: =BJ16*BK16 -> 150000 | BO16: =BM16*BN16 -> 0 | BP16: 6 | BQ16: 150000 | BR16: =BP16*BQ16 -> 900000 | BU16: =BS16*BT16 -> 0 | BV16: 1.5 | BW16: 150000 | BX16: =BV16*BW16 -> 225000 | BY16: 1.5 | BZ16: 150000 | CA16: =BY16*BZ16 -> 225000 | CD16: =CB16*CC16 -> 0 | CG16: =CE16*CF16 -> 0 | CJ16: =CH16*CI16 -> 0 | CK16: 2 | CL16: 150000 | CM16: =CK16*CL16 -> 300000 | CP16: =CN16*CO16 -> 0 | CS16: =CQ16*CR16 -> 0 | CT16: =E16+H16+K16+N16+Q16+T16+W16+Z16+AC16+AF16+AI16+AL16+AO16+AR16+AU16+AX16+BA16+BD16+BG16+BJ16+BM16+BP16+BS16+BV16+BY16+CB16+CE16+CH16+CK16+CN16+CQ16 -> 26.5 | CU16: =G16+J16+M16+P16+S16+V16+Y16+AB16+AE16+AH16+AK16+AN16+AQ16+AT16+AW16+AZ16+BC16+BF16+BI16+BL16+BO16+BR16+BU16+BX16+CA16+CD16+CG16+CJ16+CM16+CP16+CS16 -> 3975000
B17: Daging Has Dalam | C17: kg | D17: 135000 | E17: 10.5 | F17: 150000 | G17: =E17*F17 -> 1575000 | J17: =H17*I17 -> 0 | K17: 2.5 | L17: 150000 | M17: =K17*L17 -> 375000 | N17: 10 | O17: 150000 | P17: =N17*O17 -> 1500000 | S17: =Q17*R17 -> 0 | V17: =T17*U17 -> 0 | Y17: =W17*X17 -> 0 | Z17: 7.5 | AA17: 150000 | AB17: =Z17*AA17 -> 1125000 | AE17: =AC17*AD17 -> 0 | AF17: 10 | AG17: 150000 | AH17: =AF17*AG17 -> 1500000 | AI17: 11 | AJ17: 150000 | AK17: =AI17*AJ17 -> 1650000 | AN17: =AL17*AM17 -> 0 | AQ17: =AO17*AP17 -> 0 | AT17: =AR17*AS17 -> 0 | AU17: 8 | AV17: 150000 | AW17: =AU17*AV17 -> 1200000 | AZ17: =AX17*AY17 -> 0 | BC17: =BA17*BB17 -> 0 | BF17: =BD17*BE17 -> 0 | BI17: =BG17*BH17 -> 0 | BL17: =BJ17*BK17 -> 0 | BM17: 10.5 | BN17: 150000 | BO17: =BM17*BN17 -> 1575000 | BR17: =BP17*BQ17 -> 0 | BS17: 3 | BT17: 150000 | BU17: =BS17*BT17 -> 450000 | BV17: 11.5 | BW17: 150000 | BX17: =BV17*BW17 -> 1725000 | BY17: 8.5 | BZ17: 150000 | CA17: =BY17*BZ17 -> 1275000 | CB17: 1.4 | CC17: 150000 | CD17: =CB17*CC17 -> 210000 | CG17: =CE17*CF17 -> 0 | CH17: 8 | CI17: 150000 | CJ17: =CH17*CI17 -> 1200000 | CM17: =CK17*CL17 -> 0 | CP17: =CN17*CO17 -> 0 | CS17: =CQ17*CR17 -> 0 | CT17: =E17+H17+K17+N17+Q17+T17+W17+Z17+AC17+AF17+AI17+AL17+AO17+AR17+AU17+AX17+BA17+BD17+BG17+BJ17+BM17+BP17+BS17+BV17+BY17+CB17+CE17+CH17+CK17+CN17+CQ17 -> 102.4 | CU17: =G17+J17+M17+P17+S17+V17+Y17+AB17+AE17+AH17+AK17+AN17+AQ17+AT17+AW17+AZ17+BC17+BF17+BI17+BL17+BO17+BR17+BU17+BX17+CA17+CD17+CG17+CJ17+CM17+CP17+CS17 -> 15360000
B18: Sosis ayam @15 | C18: pak | D18: 23000 | G18: =E18*F18 -> 0 | J18: =H18*I18 -> 0 | M18: =K18*L18 -> 0 | P18: =N18*O18 -> 0 | S18: =Q18*R18 -> 0 | V18: =T18*U18 -> 0 | Y18: =W18*X18 -> 0 | AB18: =Z18*AA18 -> 0 | AE18: =AC18*AD18 -> 0 | AH18: =AF18*AG18 -> 0 | AK18: =AI18*AJ18 -> 0 | AN18: =AL18*AM18 -> 0 | AQ18: =AO18*AP18 -> 0 | AT18: =AR18*AS18 -> 0 | AW18: =AU18*AV18 -> 0 | AZ18: =AX18*AY18 -> 0 | BC18: =BA18*BB18 -> 0 | BF18: =BD18*BE18 -> 0 | BI18: =BG18*BH18 -> 0 | BL18: =BJ18*BK18 -> 0 | BO18: =BM18*BN18 -> 0 | BR18: =BP18*BQ18 -> 0 | BU18: =BS18*BT18 -> 0 | BX18: =BV18*BW18 -> 0 | CA18: =BY18*BZ18 -> 0 | CD18: =CB18*CC18 -> 0 | CG18: =CE18*CF18 -> 0 | CJ18: =CH18*CI18 -> 0 | CM18: =CK18*CL18 -> 0 | CP18: =CN18*CO18 -> 0 | CS18: =CQ18*CR18 -> 0 | CT18: =E18+H18+K18+N18+Q18+T18+W18+Z18+AC18+AF18+AI18+AL18+AO18+AR18+AU18+AX18+BA18+BD18+BG18+BJ18+BM18+BP18+BS18+BV18+BY18+CB18+CE18+CH18+CK18+CN18+CQ18 -> 0 | CU18: =G18+J18+M18+P18+S18+V18+Y18+AB18+AE18+AH18+AK18+AN18+AQ18+AT18+AW18+AZ18+BC18+BF18+BI18+BL18+BO18+BR18+BU18+BX18+CA18+CD18+CG18+CJ18+CM18+CP18+CS18 -> 0
B19: Gol Ikan
B20: Fillet Tenggiri | C20: kg | D20: 110000 | G20: =E20*F20 -> 0 | H20: 0.5 | I20: 110000 | J20: =H20*I20 -> 55000 | M20: =K20*L20 -> 0 | P20: =N20*O20 -> 0 | S20: =Q20*R20 -> 0 | T20: 2.5 | U20: 110000 | V20: =T20*U20 -> 275000 | Y20: =W20*X20 -> 0 | Z20: 0.5 | AA20: 110000 | AB20: =Z20*AA20 -> 55000 | AE20: =AC20*AD20 -> 0 | AH20: =AF20*AG20 -> 0 | AI20: 0.5 | AJ20: 110000 | AK20: =AI20*AJ20 -> 55000 | AN20: =AL20*AM20 -> 0 | AQ20: =AO20*AP20 -> 0 | AT20: =AR20*AS20 -> 0 | AW20: =AU20*AV20 -> 0 | AX20: 2.5 | AY20: 110000 | AZ20: =AX20*AY20 -> 275000 | BA20: 0.5 | BB20: 114000 | BC20: =BA20*BB20 -> 57000 | BD20: 0.5 | BE20: 114000 | BF20: =BD20*BE20 -> 57000 | BI20: =BG20*BH20 -> 0 | BL20: =BJ20*BK20 -> 0 | BO20: =BM20*BN20 -> 0 | BR20: =BP20*BQ20 -> 0 | BS20: 0.5 | BT20: 114000 | BU20: =BS20*BT20 -> 57000 | BX20: =BV20*BW20 -> 0 | CA20: =BY20*BZ20 -> 0 | CB20: 3.5 | CC20: 115000 | CD20: =CB20*CC20 -> 402500 | CG20: =CE20*CF20 -> 0 | CJ20: =CH20*CI20 -> 0 | CM20: =CK20*CL20 -> 0 | CP20: =CN20*CO20 -> 0 | CS20: =CQ20*CR20 -> 0 | CT20: =E20+H20+K20+N20+Q20+T20+W20+Z20+AC20+AF20+AI20+AL20+AO20+AR20+AU20+AX20+BA20+BD20+BG20+BJ20+BM20+BP20+BS20+BV20+BY20+CB20+CE20+CH20+CK20+CN20+CQ20 -> 11.5 | CU20: =G20+J20+M20+P20+S20+V20+Y20+AB20+AE20+AH20+AK20+AN20+AQ20+AT20+AW20+AZ20+BC20+BF20+BI20+BL20+BO20+BR20+BU20+BX20+CA20+CD20+CG20+CJ20+CM20+CP20+CS20 -> 1288500
